Workbook

Sheet Bright
A1: BẢNG THANH TOÁN LƯƠNG THUYỀN VIÊN TÀU INLACO BRIGHT
A2: THÁNG 3 - 2026
C3: 31 | T3: 26158 | W3: Đơn vị tính : VNĐ
A4: Tt | B4: SĐK | C4: Họ và Tên | D4: Chức | E4: Ngày | F4: Ngày | H4: Lương | J4: Ngoài | L4: Tiền | N4: Tiền | P4: Phụ cấp | Q4: Tổng | R4: BHXH, TN | S4: Đoàn phí | T4: TV nhận | U4: Nợ | V4: Lương để lại | W4: Ghi
D5: danh | E5: nhập tàu | F5: công | H5: chính | J5: giờ | L5: phép | N5: phụ cấp | P5: đào tạo | Q5: lương | T5: trên tàu | V5: gia đình | W5: chú
A6: 1 | B6: 2114 | C6: Vũ Hồng Quyết | D6: Capt. | E6: 45821 | F6: 31 | G6: 24765000 | H6: =ROUND(G6*F6/$C$3,0) -> 24765000 | I6: 28194000 | J6: =ROUND(I6*F6/$C$3,0) -> 28194000 | K6: 15240000 | L6: =ROUND(K6*F6/$C$3,0) -> 15240000 | M6: 6921000 | N6: =ROUND(M6*F6/$C$3,0) -> 6921000 | O6: 14000000 | P6: =ROUND(O6*F6/$C$3,0) -> 14000000 | Q6: =ROUND(H6+J6+L6+N6+P6,0) -> 89120000 | R6: =VLOOKUP(B6,'[1]Đi tàu'!$B$7:$F$119,5,FALSE) -> 1080000 | S6: =VLOOKUP(B6,[2]T3!$B$7:$F$116,5,FALSE) -> 60000 | T6: =ROUND(200*$T$3,0) -> 5231600 | V6: =ROUND(Q6-R6-S6-T6-U6,0) -> 82748400
A7: 2 | B7: 1613 | C7: Đào Ngọc Dưỡng | D7: C/O | E7: 45821 | F7: 31 | G7: 19110000 | H7: =ROUND(G7*F7/$C$3,0) -> 19110000 | I7: 21756000 | J7: =ROUND(I7*F7/$C$3,0) -> 21756000 | K7: 11760000 | L7: =ROUND(K7*F7/$C$3,0) -> 11760000 | M7: 7004000 | N7: =ROUND(M7*F7/$C$3,0) -> 7004000 | Q7: =ROUND(H7+J7+L7+N7+P7,0) -> 59630000 | R7: =VLOOKUP(B7,'[1]Đi tàu'!$B$7:$F$119,5,FALSE) -> 810000 | S7: =VLOOKUP(B7,[2]T3!$B$7:$F$116,5,FALSE) -> 45000 | T7: =ROUND(200*$T$3,0) -> 5231600 | V7: =ROUND(Q7-R7-S7-T7-U7,0) -> 53543400
A8: 3 | B8: 1449 | C8: Lê Văn Cường | D8: 2/O | E8: 45821 | F8: 31 | G8: 11895000 | H8: =ROUND(G8*F8/$C$3,0) -> 11895000 | I8: 13542000 | J8: =ROUND(I8*F8/$C$3,0) -> 13542000 | K8: 7320000 | L8: =ROUND(K8*F8/$C$3,0) -> 7320000 | M8: 6323000 | N8: =ROUND(M8*F8/$C$3,0) -> 6323000 | Q8: =ROUND(H8+J8+L8+N8+P8,0) -> 39080000 | R8: =VLOOKUP(B8,'[1]Đi tàu'!$B$7:$F$119,5,FALSE) -> 720000 | S8: =VLOOKUP(B8,[2]T3!$B$7:$F$116,5,FALSE) -> 40000 | T8: =ROUND(200*$T$3,0) -> 5231600 | V8: =ROUND(Q8-R8-S8-T8-U8,0) -> 33088400
A9: 4 | B9: 3050 | C9: Phạm Đại Dương | D9: 3/O | E9: 46007 | F9: 31 | G9: 10725000 | H9: =ROUND(G9*F9/$C$3,0) -> 10725000 | I9: 12210000 | J9: =ROUND(I9*F9/$C$3,0) -> 12210000 | K9: 6600000 | L9: =ROUND(K9*F9/$C$3,0) -> 6600000 | M9: 6035000 | N9: =ROUND(M9*F9/$C$3,0) -> 6035000 | Q9: =ROUND(H9+J9+L9+N9+P9,0) -> 35570000 | R9: =VLOOKUP(B9,'[1]Đi tàu'!$B$7:$F$119,5,FALSE) -> 675000 | S9: =VLOOKUP(B9,[2]T3!$B$7:$F$116,5,FALSE) -> 37500 | T9: =ROUND(200*$T$3,0) -> 5231600 | V9: =ROUND(Q9-R9-S9-T9-U9,0) -> 29625900
A10: 5 | B10: 1572 | C10: Nguyễn Văn Trung | D10: C/E | E10: 45824 | F10: 31 | G10: 22620000 | H10: =ROUND(G10*F10/$C$3,0) -> 22620000 | I10: 25752000 | J10: =ROUND(I10*F10/$C$3,0) -> 25752000 | K10: 13920000 | L10: =ROUND(K10*F10/$C$3,0) -> 13920000 | M10: 4318000 | N10: =ROUND(M10*F10/$C$3,0) -> 4318000 | O10: 12000000 | P10: =ROUND(O10*F10/$C$3,0) -> 12000000 | Q10: =ROUND(H10+J10+L10+N10+P10,0) -> 78610000 | R10: =VLOOKUP(B10,'[1]Đi tàu'!$B$7:$F$119,5,FALSE) -> 1035000 | S10: =VLOOKUP(B10,[2]T3!$B$7:$F$116,5,FALSE) -> 57500 | T10: =ROUND(200*$T$3,0) -> 5231600 | V10: =ROUND(Q10-R10-S10-T10-U10,0) -> 72285900 | W10: Lên 16/12/25
A11: 6 | B11: 1699 | C11: Nguyễn Văn Tuấn | D11: 1/E | E11: 45821 | F11: 31 | G11: 19110000 | H11: =ROUND(G11*F11/$C$3,0) -> 19110000 | I11: 21756000 | J11: =ROUND(I11*F11/$C$3,0) -> 21756000 | K11: 11760000 | L11: =ROUND(K11*F11/$C$3,0) -> 11760000 | M11: 7004000 | N11: =ROUND(M11*F11/$C$3,0) -> 7004000 | Q11: =ROUND(H11+J11+L11+N11+P11,0) -> 59630000 | R11: =VLOOKUP(B11,'[1]Đi tàu'!$B$7:$F$119,5,FALSE) -> 810000 | S11: =VLOOKUP(B11,[2]T3!$B$7:$F$116,5,FALSE) -> 45000 | T11: =ROUND(200*$T$3,0) -> 5231600 | V11: =ROUND(Q11-R11-S11-T11-U11,0) -> 53543400 | W11: Lên 16/12/25
A12: 7 | B12: 1137 | C12: Ng. Thành Trung | D12: 2/E | E12: 46007 | F12: 31 | G12: 11895000 | H12: =ROUND(G12*F12/$C$3,0) -> 11895000 | I12: 13542000 | J12: =ROUND(I12*F12/$C$3,0) -> 13542000 | K12: 7320000 | L12: =ROUND(K12*F12/$C$3,0) -> 7320000 | M12: 6323000 | N12: =ROUND(M12*F12/$C$3,0) -> 6323000 | Q12: =ROUND(H12+J12+L12+N12+P12,0) -> 39080000 | R12: =VLOOKUP(B12,'[1]Đi tàu'!$B$7:$F$119,5,FALSE) -> 720000 | S12: =VLOOKUP(B12,[2]T3!$B$7:$F$116,5,FALSE) -> 40000 | T12: =ROUND(200*$T$3,0) -> 5231600 | V12: =ROUND(Q12-R12-S12-T12-U12,0) -> 33088400
A13: 8 | B13: TV334 | C13: Nguyễn Văn San | D13: 3/E | E13: 45821 | F13: 31 | G13: 10725000 | H13: =ROUND(G13*F13/$C$3,0) -> 10725000 | I13: 12210000 | J13: =ROUND(I13*F13/$C$3,0) -> 12210000 | K13: 6600000 | L13: =ROUND(K13*F13/$C$3,0) -> 6600000 | M13: 6035000 | N13: =ROUND(M13*F13/$C$3,0) -> 6035000 | Q13: =ROUND(H13+J13+L13+N13+P13,0) -> 35570000 | R13: =VLOOKUP(B13,'[1]Đi tàu'!$B$7:$F$119,5,FALSE) -> 2062500 | T13: =ROUND(200*$T$3,0) -> 5231600 | V13: =ROUND(Q13-R13-S13-T13-U13,0) -> 28275900
A14: 9 | B14: 1512 | C14: Đặng Đức Nhuận | D14: BSN | E14: 45821 | F14: 31 | G14: 8385000 | H14: =ROUND(G14*F14/$C$3,0) -> 8385000 | I14: 9546000 | J14: =ROUND(I14*F14/$C$3,0) -> 9546000 | K14: 5160000 | L14: =ROUND(K14*F14/$C$3,0) -> 5160000 | M14: 4909000 | N14: =ROUND(M14*F14/$C$3,0) -> 4909000 | Q14: =ROUND(H14+J14+L14+N14+P14,0) -> 28000000 | R14: =VLOOKUP(B14,'[1]Đi tàu'!$B$7:$F$119,5,FALSE) -> 585000 | S14: =VLOOKUP(B14,[2]T3!$B$7:$F$116,5,FALSE) -> 32500 | T14: =ROUND(100*$T$3,0) -> 2615800 | V14: =ROUND(Q14-R14-S14-T14-U14,0) -> 24766700
A15: 10 | B15: 2904 | C15: Hoàng Văn Hiệp | D15: AB | E15: 45882 | F15: 31 | G15: 6630000 | H15: =ROUND(G15*F15/$C$3,0) -> 6630000 | I15: 7548000 | J15: =ROUND(I15*F15/$C$3,0) -> 7548000 | K15: 4080000 | L15: =ROUND(K15*F15/$C$3,0) -> 4080000 | M15: 4742000 | N15: =ROUND(M15*F15/$C$3,0) -> 4742000 | Q15: =ROUND(H15+J15+L15+N15+P15,0) -> 23000000 | R15: =VLOOKUP(B15,'[1]Đi tàu'!$B$7:$F$119,5,FALSE) -> 540000 | S15: =VLOOKUP(B15,[2]T3!$B$7:$F$116,5,FALSE) -> 30000 | T15: =ROUND(100*$T$3,0) -> 2615800 | V15: =ROUND(Q15-R15-S15-T15-U15,0) -> 19814200
A16: 11 | B16: 2757 | C16: Nguyễn Đức Toàn | D16: AB | E16: 45821 | F16: 31 | G16: 6630000 | H16: =ROUND(G16*F16/$C$3,0) -> 6630000 | I16: 7548000 | J16: =ROUND(I16*F16/$C$3,0) -> 7548000 | K16: 4080000 | L16: =ROUND(K16*F16/$C$3,0) -> 4080000 | M16: 4742000 | N16: =ROUND(M16*F16/$C$3,0) -> 4742000 | Q16: =ROUND(H16+J16+L16+N16+P16,0) -> 23000000 | R16: =VLOOKUP(B16,'[1]Đi tàu'!$B$7:$F$119,5,FALSE) -> 540000 | S16: =VLOOKUP(B16,[2]T3!$B$7:$F$116,5,FALSE) -> 30000 | T16: =ROUND(100*$T$3,0) -> 2615800 | V16: =ROUND(Q16-R16-S16-T16-U16,0) -> 19814200
A17: 12 | B17: 2963 | C17: Nguyễn Văn Sỹ | D17: AB | E17: 45964 | F17: 31 | G17: 6630000 | H17: =ROUND(G17*F17/$C$3,0) -> 6630000 | I17: 7548000 | J17: =ROUND(I17*F17/$C$3,0) -> 7548000 | K17: 4080000 | L17: =ROUND(K17*F17/$C$3,0) -> 4080000 | M17: 4742000 | N17: =ROUND(M17*F17/$C$3,0) -> 4742000 | Q17: =ROUND(H17+J17+L17+N17+P17,0) -> 23000000 | R17: =VLOOKUP(B17,'[1]Đi tàu'!$B$7:$F$119,5,FALSE) -> 540000 | S17: =VLOOKUP(B17,[2]T3!$B$7:$F$116,5,FALSE) -> 30000 | T17: =ROUND(100*$T$3,0) -> 2615800 | V17: =ROUND(Q17-R17-S17-T17-U17,0) -> 19814200
A18: 13 | B18: 2987 | C18: Ng. Trường Thắng | D18: AB | E18: 45821 | F18: 31 | G18: 6630000 | H18: =ROUND(G18*F18/$C$3,0) -> 6630000 | I18: 7548000 | J18: =ROUND(I18*F18/$C$3,0) -> 7548000 | K18: 4080000 | L18: =ROUND(K18*F18/$C$3,0) -> 4080000 | M18: 4742000 | N18: =ROUND(M18*F18/$C$3,0) -> 4742000 | Q18: =ROUND(H18+J18+L18+N18+P18,0) -> 23000000 | R18: =VLOOKUP(B18,'[1]Đi tàu'!$B$7:$F$119,5,FALSE) -> 540000 | S18: =VLOOKUP(B18,[2]T3!$B$7:$F$116,5,FALSE) -> 30000 | T18: =ROUND(100*$T$3,0) -> 2615800 | V18: =ROUND(Q18-R18-S18-T18-U18,0) -> 19814200 | W18: Lên 16/12/25
A19: 14 | B19: 3032 | C19: Trần Văn Đạt | D19: OS | E19: 45821 | F19: 31 | G19: 5655000 | H19: =ROUND(G19*F19/$C$3,0) -> 5655000 | I19: 6438000 | J19: =ROUND(I19*F19/$C$3,0) -> 6438000 | K19: 3480000 | L19: =ROUND(K19*F19/$C$3,0) -> 3480000 | M19: 2427000 | N19: =ROUND(M19*F19/$C$3,0) -> 2427000 | Q19: =ROUND(H19+J19+L19+N19+P19,0) -> 18000000 | R19: =VLOOKUP(B19,'[1]Đi tàu'!$B$7:$F$119,5,FALSE) -> 540000 | S19: =VLOOKUP(B19,[2]T3!$B$7:$F$116,5,FALSE) -> 30000 | T19: =ROUND(100*$T$3,0) -> 2615800 | V19: =ROUND(Q19-R19-S19-T19-U19,0) -> 14814200 | W19: Lên 13/8/25
A20: 15 | B20: 3036 | C20: Trần Quốc Anh | D20: OS | E20: 45882 | F20: 31 | G20: 5655000 | H20: =ROUND(G20*F20/$C$3,0) -> 5655000 | I20: 6438000 | J20: =ROUND(I20*F20/$C$3,0) -> 6438000 | K20: 3480000 | L20: =ROUND(K20*F20/$C$3,0) -> 3480000 | M20: 2427000 | N20: =ROUND(M20*F20/$C$3,0) -> 2427000 | Q20: =ROUND(H20+J20+L20+N20+P20,0) -> 18000000 | R20: =VLOOKUP(B20,'[1]Đi tàu'!$B$7:$F$119,5,FALSE) -> 540000 | S20: =VLOOKUP(B20,[2]T3!$B$7:$F$116,5,FALSE) -> 30000 | T20: =ROUND(100*$T$3,0) -> 2615800 | V20: =ROUND(Q20-R20-S20-T20-U20,0) -> 14814200 | W20: Lên 01/12/25
A21: 16 | B21: 2826 | C21: Bùi Hữu Thức | D21: No.1 | E21: 46007 | F21: 31 | G21: 8385000 | H21: =ROUND(G21*F21/$C$3,0) -> 8385000 | I21: 9546000 | J21: =ROUND(I21*F21/$C$3,0) -> 9546000 | K21: 5160000 | L21: =ROUND(K21*F21/$C$3,0) -> 5160000 | M21: 4909000 | N21: =ROUND(M21*F21/$C$3,0) -> 4909000 | Q21: =ROUND(H21+J21+L21+N21+P21,0) -> 28000000 | R21: =VLOOKUP(B21,'[1]Đi tàu'!$B$7:$F$119,5,FALSE) -> 585000 | S21: =VLOOKUP(B21,[2]T3!$B$7:$F$116,5,FALSE) -> 32500 | T21: =ROUND(100*$T$3,0) -> 2615800 | V21: =ROUND(Q21-R21-S21-T21-U21,0) -> 24766700
A22: 17 | B22: 2877 | C22: Trương Văn Điệp | D22: OLR | E22: 45964 | F22: 31 | G22: 6630000 | H22: =ROUND(G22*F22/$C$3,0) -> 6630000 | I22: 7548000 | J22: =ROUND(I22*F22/$C$3,0) -> 7548000 | K22: 4080000 | L22: =ROUND(K22*F22/$C$3,0) -> 4080000 | M22: 4742000 | N22: =ROUND(M22*F22/$C$3,0) -> 4742000 | Q22: =ROUND(H22+J22+L22+N22+P22,0) -> 23000000 | R22: =VLOOKUP(B22,'[1]Đi tàu'!$B$7:$F$119,5,FALSE) -> 540000 | S22: =VLOOKUP(B22,[2]T3!$B$7:$F$116,5,FALSE) -> 30000 | T22: =ROUND(100*$T$3,0) -> 2615800 | V22: =ROUND(Q22-R22-S22-T22-U22,0) -> 19814200
A23: 18 | B23: 2796 | C23: Cao Xuân Ánh | D23: OLR | E23: 45964 | F23: 31 | G23: 6630000 | H23: =ROUND(G23*F23/$C$3,0) -> 6630000 | I23: 7548000 | J23: =ROUND(I23*F23/$C$3,0) -> 7548000 | K23: 4080000 | L23: =ROUND(K23*F23/$C$3,0) -> 4080000 | M23: 4742000 | N23: =ROUND(M23*F23/$C$3,0) -> 4742000 | Q23: =ROUND(H23+J23+L23+N23+P23,0) -> 23000000 | R23: =VLOOKUP(B23,'[1]Đi tàu'!$B$7:$F$119,5,FALSE) -> 540000 | S23: =VLOOKUP(B23,[2]T3!$B$7:$F$116,5,FALSE) -> 30000 | T23: =ROUND(100*$T$3,0) -> 2615800 | V23: =ROUND(Q23-R23-S23-T23-U23,0) -> 19814200
A24: 19 | B24: 2813 | C24: Hoàng Mạnh Cường | D24: OLR | E24: 45821 | F24: 31 | G24: 6630000 | H24: =ROUND(G24*F24/$C$3,0) -> 6630000 | I24: 7548000 | J24: =ROUND(I24*F24/$C$3,0) -> 7548000 | K24: 4080000 | L24: =ROUND(K24*F24/$C$3,0) -> 4080000 | M24: 4742000 | N24: =ROUND(M24*F24/$C$3,0) -> 4742000 | Q24: =ROUND(H24+J24+L24+N24+P24,0) -> 23000000 | R24: =VLOOKUP(B24,'[1]Đi tàu'!$B$7:$F$119,5,FALSE) -> 540000 | S24: =VLOOKUP(B24,[2]T3!$B$7:$F$116,5,FALSE) -> 30000 | T24: =ROUND(100*$T$3,0) -> 2615800 | V24: =ROUND(Q24-R24-S24-T24-U24,0) -> 19814200
A25: 20 | B25: 1756 | C25: Võ Hoàng Khanh | D25: C/C | E25: 45821 | F25: 31 | G25: 8385000 | H25: =ROUND(G25*F25/$C$3,0) -> 8385000 | I25: 9546000 | J25: =ROUND(I25*F25/$C$3,0) -> 9546000 | K25: 5160000 | L25: =ROUND(K25*F25/$C$3,0) -> 5160000 | M25: 4909000 | N25: =ROUND(M25*F25/$C$3,0) -> 4909000 | Q25: =ROUND(H25+J25+L25+N25+P25,0) -> 28000000 | R25: =VLOOKUP(B25,'[1]Đi tàu'!$B$7:$F$119,5,FALSE) -> 585000 | S25: =VLOOKUP(B25,[2]T3!$B$7:$F$116,5,FALSE) -> 32500 | T25: =ROUND(100*$T$3,0) -> 2615800 | V25: =ROUND(Q25-R25-S25-T25-U25,0) -> 24766700
A26: 21 | B26: 3047 | C26: Vũ Văn Tuyền | D26: M/M | E26: 45964 | F26: 31 | G26: 5655000 | H26: =ROUND(G26*F26/$C$3,0) -> 5655000 | I26: 6438000 | J26: =ROUND(I26*F26/$C$3,0) -> 6438000 | K26: 3480000 | L26: =ROUND(K26*F26/$C$3,0) -> 3480000 | M26: 1427000 | N26: =ROUND(M26*F26/$C$3,0) -> 1427000 | Q26: =ROUND(H26+J26+L26+N26+P26,0) -> 17000000 | R26: =VLOOKUP(B26,'[1]Đi tàu'!$B$7:$F$119,5,FALSE) -> 540000 | S26: =VLOOKUP(B26,[2]T3!$B$7:$F$116,5,FALSE) -> 30000 | T26: =ROUND(100*$T$3,0) -> 2615800 | V26: =ROUND(Q26-R26-S26-T26-U26,0) -> 13814200
C27: Tổng cộng | F27: =SUM(F6:F26) -> 651 | G27: =SUM(G6:G26) -> 219375000 | H27: =SUM(H6:H26) -> 219375000 | I27: =SUM(I6:I26) -> 249750000 | J27: =SUM(J6:J26) -> 249750000 | K27: =SUM(K6:K26) -> 135000000 | L27: =SUM(L6:L26) -> 135000000 | M27: =SUM(M6:M26) -> 104165000 | ... V27: =SUM(V6:V26) -> 642641800
W29: Tp. Hồ Chí Minh, ngày tháng năm 2026
B30: Người lập | E30: P.Trưởng phòng Thuyền viên | Q30: Kế toán trưởng | U30: Tổng giám đốc

Sheet Harmony
A1: BẢNG THANH TOÁN LƯƠNG THUYỀN VIÊN TÀU INLACO HARMONY
A2: THÁNG 3 - 2026
C3: 31 | V3: 26158 | Y3: Đơn vị tính : VNĐ
A4: Tt | B4: SĐK | C4: Họ và Tên | D4: Chức | E4: Ngày | F4: Ngày | H4: Lương | J4: Ngoài | L4: Tiền | N4: Tiền | P4: Phụ cấp | R4: Phụ cấp vùng | S4: Tổng | T4: BHXH | U4: Đoàn phí | V4: TV nhận | W4: Nợ | X4: Lương để lại | Y4: Ghi
D5: danh | E5: nhập tàu | F5: công | H5: chính | J5: giờ | L5: phép | N5: phụ cấp | P5: đào tạo | R5: hoạt động | S5: lương | T5: BHTN | V5: trên tàu | X5: gia đình | Y5: chú
A6: 1 | B6: 1003 | C6: Đặng Văn Thiệp | D6: Capt. | E6: 45919 | F6: 31 | G6: 24765000 | H6: =ROUND(G6*F6/$C$3,0) -> 24765000 | I6: 28194000 | J6: =ROUND(I6*F6/$C$3,0) -> 28194000 | K6: 15240000 | L6: =ROUND(K6*F6/$C$3,0) -> 15240000 | M6: 6921000 | N6: =ROUND(M6*F6/$C$3,0) -> 6921000 | O6: 14000000 | P6: =ROUND(O6*F6/$C$3,0) -> 14000000 | Q6: 24880000 | R6: =ROUND(Q6*F6/$C$3,0) -> 24880000 | S6: =ROUND(H6+J6+L6+N6+P6+R6,0) -> 114000000 | T6: =VLOOKUP(B6,'[1]Đi tàu'!$B$7:$F$119,5,FALSE) -> 1080000 | U6: =VLOOKUP(B6,[2]T3!$B$7:$F$116,5,FALSE) -> 60000 | V6: =ROUND(200*$V$3,0) -> 5231600 | X6: =S6-T6-U6-V6-W6 -> 107628400 | AA6: =V6/26158 -> 200
A7: 2 | B7: 1857 | C7: Lê Công Sơn | D7: C/O | E7: 45919 | F7: 31 | G7: 19110000 | H7: =ROUND(G7*F7/$C$3,0) -> 19110000 | I7: 21756000 | J7: =ROUND(I7*F7/$C$3,0) -> 21756000 | K7: 11760000 | L7: =ROUND(K7*F7/$C$3,0) -> 11760000 | M7: 7004000 | N7: =ROUND(M7*F7/$C$3,0) -> 7004000 | P7: =ROUND(O7*F7/$C$3,0) -> 0 | Q7: 16670000 | R7: =ROUND(Q7*F7/$C$3,0) -> 16670000 | S7: =ROUND(H7+J7+L7+N7+P7+R7,0) -> 76300000 | T7: =VLOOKUP(B7,'[1]Đi tàu'!$B$7:$F$119,5,FALSE) -> 810000 | U7: =VLOOKUP(B7,[2]T3!$B$7:$F$116,5,FALSE) -> 45000 | V7: =ROUND(200*$V$3,0) -> 5231600 | X7: =S7-T7-U7-V7-W7 -> 70213400 | AA7: =V7/26158 -> 200
A8: 3 | B8: 3006 | C8: Thái Văn Dương | D8: 2/O | E8: 45885 | F8: 31 | G8: 11895000 | H8: =ROUND(G8*F8/$C$3,0) -> 11895000 | I8: 13542000 | J8: =ROUND(I8*F8/$C$3,0) -> 13542000 | K8: 7320000 | L8: =ROUND(K8*F8/$C$3,0) -> 7320000 | M8: 6323000 | N8: =ROUND(M8*F8/$C$3,0) -> 6323000 | P8: =ROUND(O8*F8/$C$3,0) -> 0 | Q8: 10920000 | R8: =ROUND(Q8*F8/$C$3,0) -> 10920000 | S8: =ROUND(H8+J8+L8+N8+P8+R8,0) -> 50000000 | T8: =VLOOKUP(B8,'[1]Đi tàu'!$B$7:$F$119,5,FALSE) -> 720000 | U8: =VLOOKUP(B8,[2]T3!$B$7:$F$116,5,FALSE) -> 40000 | V8: =ROUND(200*$V$3,0) -> 5231600 | X8: =S8-T8-U8-V8-W8 -> 44008400 | Y8: Lên 4/2/26 | AA8: =V8/26158 -> 200
A9: 4 | B9: 1853 | C9: Ng. Hồng Sơn | D9: 3/O | E9: 45919 | F9: 31 | G9: 10725000 | H9: =ROUND(G9*F9/$C$3,0) -> 10725000 | I9: 12210000 | J9: =ROUND(I9*F9/$C$3,0) -> 12210000 | K9: 6600000 | L9: =ROUND(K9*F9/$C$3,0) -> 6600000 | M9: 6035000 | N9: =ROUND(M9*F9/$C$3,0) -> 6035000 | P9: =ROUND(O9*F9/$C$3,0) -> 0 | Q9: 9930000 | R9: =ROUND(Q9*F9/$C$3,0) -> 9930000 | S9: =ROUND(H9+J9+L9+N9+P9+R9,0) -> 45500000 | T9: =VLOOKUP(B9,'[1]Đi tàu'!$B$7:$F$119,5,FALSE) -> 675000 | U9: =VLOOKUP(B9,[2]T3!$B$7:$F$116,5,FALSE) -> 37500 | V9: =ROUND(200*$V$3,0) -> 5231600 | X9: =S9-T9-U9-V9-W9 -> 39555900 | Y9: Lên 4/2/26 | AA9: =V9/26158 -> 200
A10: 5 | B10: 744 | C10: Phạm Phương Nam | D10: C/E | E10: 45919 | F10: 31 | G10: 22620000 | H10: =ROUND(G10*F10/$C$3,0) -> 22620000 | I10: 25752000 | J10: =ROUND(I10*F10/$C$3,0) -> 25752000 | K10: 13920000 | L10: =ROUND(K10*F10/$C$3,0) -> 13920000 | M10: 4318000 | N10: =ROUND(M10*F10/$C$3,0) -> 4318000 | O10: 12000000 | P10: =ROUND(O10*F10/$C$3,0) -> 12000000 | Q10: 21990000 | R10: =ROUND(Q10*F10/$C$3,0) -> 21990000 | S10: =ROUND(H10+J10+L10+N10+P10+R10,0) -> 100600000 | T10: =VLOOKUP(B10,'[1]Đi tàu'!$B$7:$F$119,5,FALSE) -> 1035000 | U10: =VLOOKUP(B10,[2]T3!$B$7:$F$116,5,FALSE) -> 57500 | V10: =ROUND(200*$V$3,0) -> 5231600 | X10: =S10-T10-U10-V10-W10 -> 94275900 | AA10: =V10/26158 -> 200
A11: 6 | B11: 1565 | C11: Trần Hồng Tự | D11: 1/E | E11: 45885 | F11: 31 | G11: 19110000 | H11: =ROUND(G11*F11/$C$3,0) -> 19110000 | I11: 21756000 | J11: =ROUND(I11*F11/$C$3,0) -> 21756000 | K11: 11760000 | L11: =ROUND(K11*F11/$C$3,0) -> 11760000 | M11: 7004000 | N11: =ROUND(M11*F11/$C$3,0) -> 7004000 | P11: =ROUND(O11*F11/$C$3,0) -> 0 | Q11: 16670000 | R11: =ROUND(Q11*F11/$C$3,0) -> 16670000 | S11: =ROUND(H11+J11+L11+N11+P11+R11,0) -> 76300000 | T11: =VLOOKUP(B11,'[1]Đi tàu'!$B$7:$F$119,5,FALSE) -> 810000 | U11: =VLOOKUP(B11,[2]T3!$B$7:$F$116,5,FALSE) -> 45000 | V11: =ROUND(200*$V$3,0) -> 5231600 | X11: =S11-T11-U11-V11-W11 -> 70213400 | AA11: =V11/26158 -> 200
A12: 7 | B12: 2920 | C12: Châu Anh Tú | D12: 2/E | E12: 45919 | F12: 31 | G12: 11895000 | H12: =ROUND(G12*F12/$C$3,0) -> 11895000 | I12: 13542000 | J12: =ROUND(I12*F12/$C$3,0) -> 13542000 | K12: 7320000 | L12: =ROUND(K12*F12/$C$3,0) -> 7320000 | M12: 6323000 | N12: =ROUND(M12*F12/$C$3,0) -> 6323000 | P12: =ROUND(O12*F12/$C$3,0) -> 0 | Q12: 10920000 | R12: =ROUND(Q12*F12/$C$3,0) -> 10920000 | S12: =ROUND(H12+J12+L12+N12+P12+R12,0) -> 50000000 | T12: =VLOOKUP(B12,'[1]Đi tàu'!$B$7:$F$119,5,FALSE) -> 720000 | U12: =VLOOKUP(B12,[2]T3!$B$7:$F$116,5,FALSE) -> 40000 | V12: =ROUND(200*$V$3,0) -> 5231600 | X12: =S12-T12-U12-V12-W12 -> 44008400 | AA12: =V12/26158 -> 200
A13: 8 | B13: 2690 | C13: Bùi Hoàng Phú | D13: 3/E | E13: 45885 | F13: 31 | G13: 10725000 | H13: =ROUND(G13*F13/$C$3,0) -> 10725000 | I13: 12210000 | J13: =ROUND(I13*F13/$C$3,0) -> 12210000 | K13: 6600000 | L13: =ROUND(K13*F13/$C$3,0) -> 6600000 | M13: 6035000 | N13: =ROUND(M13*F13/$C$3,0) -> 6035000 | P13: =ROUND(O13*F13/$C$3,0) -> 0 | Q13: 9930000 | R13: =ROUND(Q13*F13/$C$3,0) -> 9930000 | S13: =ROUND(H13+J13+L13+N13+P13+R13,0) -> 45500000 | T13: =VLOOKUP(B13,'[1]Đi tàu'!$B$7:$F$119,5,FALSE) -> 675000 | U13: =VLOOKUP(B13,[2]T3!$B$7:$F$116,5,FALSE) -> 37500 | V13: =ROUND(200*$V$3,0) -> 5231600 | X13: =S13-T13-U13-V13-W13 -> 39555900 | AA13: =V13/26158 -> 200
A14: 9 | B14: 1440 | C14: Vũ Văn Bắc | D14: BSN | E14: 45919 | F14: 31 | G14: 8385000 | H14: =ROUND(G14*F14/$C$3,0) -> 8385000 | I14: 9546000 | J14: =ROUND(I14*F14/$C$3,0) -> 9546000 | K14: 5160000 | L14: =ROUND(K14*F14/$C$3,0) -> 5160000 | M14: 4909000 | N14: =ROUND(M14*F14/$C$3,0) -> 4909000 | P14: =ROUND(O14*F14/$C$3,0) -> 0 | Q14: 7000000 | R14: =ROUND(Q14*F14/$C$3,0) -> 7000000 | S14: =ROUND(H14+J14+L14+N14+P14+R14,0) -> 35000000 | T14: =VLOOKUP(B14,'[1]Đi tàu'!$B$7:$F$119,5,FALSE) -> 585000 | U14: =VLOOKUP(B14,[2]T3!$B$7:$F$116,5,FALSE) -> 32500 | V14: =ROUND(100*$V$3,0) -> 2615800 | X14: =S14-T14-U14-V14-W14 -> 31766700 | AA14: =V14/26158 -> 100
A15: 10 | B15: 2782 | C15: Phạm Xuân Trường | D15: AB | E15: 45919 | F15: 31 | G15: 6630000 | H15: =ROUND(G15*F15/$C$3,0) -> 6630000 | I15: 7548000 | J15: =ROUND(I15*F15/$C$3,0) -> 7548000 | K15: 4080000 | L15: =ROUND(K15*F15/$C$3,0) -> 4080000 | M15: 4742000 | N15: =ROUND(M15*F15/$C$3,0) -> 4742000 | P15: =ROUND(O15*F15/$C$3,0) -> 0 | Q15: 4700000 | R15: =ROUND(Q15*F15/$C$3,0) -> 4700000 | S15: =ROUND(H15+J15+L15+N15+P15+R15,0) -> 27700000 | T15: =VLOOKUP(B15,'[1]Đi tàu'!$B$7:$F$119,5,FALSE) -> 540000 | U15: =VLOOKUP(B15,[2]T3!$B$7:$F$116,5,FALSE) -> 30000 | V15: =ROUND(100*$V$3,0) -> 2615800 | X15: =S15-T15-U15-V15-W15 -> 24514200 | AA15: =V15/26158 -> 100
A16: 11 | B16: 2872 | C16: Lê Văn Nghĩa | D16: AB | E16: 45919 | F16: 31 | G16: 6630000 | H16: =ROUND(G16*F16/$C$3,0) -> 6630000 | I16: 7548000 | J16: =ROUND(I16*F16/$C$3,0) -> 7548000 | K16: 4080000 | L16: =ROUND(K16*F16/$C$3,0) -> 4080000 | M16: 4742000 | N16: =ROUND(M16*F16/$C$3,0) -> 4742000 | P16: =ROUND(O16*F16/$C$3,0) -> 0 | Q16: 4700000 | R16: =ROUND(Q16*F16/$C$3,0) -> 4700000 | S16: =ROUND(H16+J16+L16+N16+P16+R16,0) -> 27700000 | T16: =VLOOKUP(B16,'[1]Đi tàu'!$B$7:$F$119,5,FALSE) -> 540000 | U16: =VLOOKUP(B16,[2]T3!$B$7:$F$116,5,FALSE) -> 30000 | V16: =ROUND(100*$V$3,0) -> 2615800 | X16: =S16-T16-U16-V16-W16 -> 24514200 | AA16: =V16/26158 -> 100
A17: 12 | B17: 2538 | C17: Lê Hồng Sơn | D17: AB | E17: 45919 | F17: 31 | G17: 6630000 | H17: =ROUND(G17*F17/$C$3,0) -> 6630000 | I17: 7548000 | J17: =ROUND(I17*F17/$C$3,0) -> 7548000 | K17: 4080000 | L17: =ROUND(K17*F17/$C$3,0) -> 4080000 | M17: 4742000 | N17: =ROUND(M17*F17/$C$3,0) -> 4742000 | P17: =ROUND(O17*F17/$C$3,0) -> 0 | Q17: 4700000 | R17: =ROUND(Q17*F17/$C$3,0) -> 4700000 | S17: =ROUND(H17+J17+L17+N17+P17+R17,0) -> 27700000 | T17: =VLOOKUP(B17,'[1]Đi tàu'!$B$7:$F$119,5,FALSE) -> 540000 | U17: =VLOOKUP(B17,[2]T3!$B$7:$F$116,5,FALSE) -> 30000 | V17: =ROUND(100*$V$3,0) -> 2615800 | X17: =S17-T17-U17-V17-W17 -> 24514200 | Y17: Lên 4/2/26 | AA17: =V17/26158 -> 100
A18: 13 | B18: 3041 | C18: Ng. Quang Dũng | D18: OS | E18: 45919 | F18: 31 | G18: 5655000 | H18: =ROUND(G18*F18/$C$3,0) -> 5655000 | I18: 6438000 | J18: =ROUND(I18*F18/$C$3,0) -> 6438000 | K18: 3480000 | L18: =ROUND(K18*F18/$C$3,0) -> 3480000 | M18: 2427000 | N18: =ROUND(M18*F18/$C$3,0) -> 2427000 | P18: =ROUND(O18*F18/$C$3,0) -> 0 | Q18: 3700000 | R18: =ROUND(Q18*F18/$C$3,0) -> 3700000 | S18: =ROUND(H18+J18+L18+N18+P18+R18,0) -> 21700000 | T18: =VLOOKUP(B18,'[1]Đi tàu'!$B$7:$F$119,5,FALSE) -> 540000 | U18: =VLOOKUP(B18,[2]T3!$B$7:$F$116,5,FALSE) -> 30000 | V18: =ROUND(100*$V$3,0) -> 2615800 | X18: =S18-T18-U18-V18-W18 -> 18514200 | AA18: =V18/26158 -> 100
A19: 14 | B19: 1375 | C19: Nguyễn Đức Điển | D19: No.1 | E19: 45885 | F19: 31 | G19: 8385000 | H19: =ROUND(G19*F19/$C$3,0) -> 8385000 | I19: 9546000 | J19: =ROUND(I19*F19/$C$3,0) -> 9546000 | K19: 5160000 | L19: =ROUND(K19*F19/$C$3,0) -> 5160000 | M19: 4909000 | N19: =ROUND(M19*F19/$C$3,0) -> 4909000 | P19: =ROUND(O19*F19/$C$3,0) -> 0 | Q19: 7000000 | R19: =ROUND(Q19*F19/$C$3,0) -> 7000000 | S19: =ROUND(H19+J19+L19+N19+P19+R19,0) -> 35000000 | T19: =VLOOKUP(B19,'[1]Đi tàu'!$B$7:$F$119,5,FALSE) -> 585000 | U19: =VLOOKUP(B19,[2]T3!$B$7:$F$116,5,FALSE) -> 32500 | V19: =ROUND(100*$V$3,0) -> 2615800 | X19: =S19-T19-U19-V19-W19 -> 31766700 | AA19: =V19/26158 -> 100
A20: 15 | B20: 2706 | C20: Trần Ngọc Khải | D20: OLR | E20: 45919 | F20: 31 | G20: 6630000 | H20: =ROUND(G20*F20/$C$3,0) -> 6630000 | I20: 7548000 | J20: =ROUND(I20*F20/$C$3,0) -> 7548000 | K20: 4080000 | L20: =ROUND(K20*F20/$C$3,0) -> 4080000 | M20: 4742000 | N20: =ROUND(M20*F20/$C$3,0) -> 4742000 | P20: =ROUND(O20*F20/$C$3,0) -> 0 | Q20: 4700000 | R20: =ROUND(Q20*F20/$C$3,0) -> 4700000 | S20: =ROUND(H20+J20+L20+N20+P20+R20,0) -> 27700000 | T20: =VLOOKUP(B20,'[1]Đi tàu'!$B$7:$F$119,5,FALSE) -> 540000 | U20: =VLOOKUP(B20,[2]T3!$B$7:$F$116,5,FALSE) -> 30000 | V20: =ROUND(100*$V$3,0) -> 2615800 | X20: =S20-T20-U20-V20-W20 -> 24514200 | AA20: =V20/26158 -> 100
A21: 16 | B21: 2547 | C21: Nguyễn Văn Khanh | D21: OLR | E21: 45885 | F21: 31 | G21: 6630000 | H21: =ROUND(G21*F21/$C$3,0) -> 6630000 | I21: 7548000 | J21: =ROUND(I21*F21/$C$3,0) -> 7548000 | K21: 4080000 | L21: =ROUND(K21*F21/$C$3,0) -> 4080000 | M21: 4742000 | N21: =ROUND(M21*F21/$C$3,0) -> 4742000 | P21: =ROUND(O21*F21/$C$3,0) -> 0 | Q21: 4700000 | R21: =ROUND(Q21*F21/$C$3,0) -> 4700000 | S21: =ROUND(H21+J21+L21+N21+P21+R21,0) -> 27700000 | T21: =VLOOKUP(B21,'[1]Đi tàu'!$B$7:$F$119,5,FALSE) -> 540000 | U21: =VLOOKUP(B21,[2]T3!$B$7:$F$116,5,FALSE) -> 30000 | V21: =ROUND(100*$V$3,0) -> 2615800 | X21: =S21-T21-U21-V21-W21 -> 24514200 | AA21: =V21/26158 -> 100
A22: 17 | B22: 2760 | C22: Phạm Hoàng Hải | D22: OLR | E22: 45885 | F22: 31 | G22: 6630000 | H22: =ROUND(G22*F22/$C$3,0) -> 6630000 | I22: 7548000 | J22: =ROUND(I22*F22/$C$3,0) -> 7548000 | K22: 4080000 | L22: =ROUND(K22*F22/$C$3,0) -> 4080000 | M22: 4742000 | N22: =ROUND(M22*F22/$C$3,0) -> 4742000 | P22: =ROUND(O22*F22/$C$3,0) -> 0 | Q22: 4700000 | R22: =ROUND(Q22*F22/$C$3,0) -> 4700000 | S22: =ROUND(H22+J22+L22+N22+P22+R22,0) -> 27700000 | T22: =VLOOKUP(B22,'[1]Đi tàu'!$B$7:$F$119,5,FALSE) -> 540000 | U22: =VLOOKUP(B22,[2]T3!$B$7:$F$116,5,FALSE) -> 30000 | V22: =ROUND(100*$V$3,0) -> 2615800 | X22: =S22-T22-U22-V22-W22 -> 24514200 | AA22: =V22/26158 -> 100
A23: 18 | B23: 2095 | C23: Trần Minh Thanh | D23: C/C | E23: 45919 | F23: 31 | G23: 8385000 | H23: =ROUND(G23*F23/$C$3,0) -> 8385000 | I23: 9546000 | J23: =ROUND(I23*F23/$C$3,0) -> 9546000 | K23: 5160000 | L23: =ROUND(K23*F23/$C$3,0) -> 5160000 | M23: 4909000 | N23: =ROUND(M23*F23/$C$3,0) -> 4909000 | P23: =ROUND(O23*F23/$C$3,0) -> 0 | Q23: 5800000 | R23: =ROUND(Q23*F23/$C$3,0) -> 5800000 | S23: =ROUND(H23+J23+L23+N23+P23+R23,0) -> 33800000 | T23: =VLOOKUP(B23,'[1]Đi tàu'!$B$7:$F$119,5,FALSE) -> 585000 | U23: =VLOOKUP(B23,[2]T3!$B$7:$F$116,5,FALSE) -> 32500 | V23: =ROUND(100*$V$3,0) -> 2615800 | X23: =S23-T23-U23-V23-W23 -> 30566700 | AA23: =V23/26158 -> 100
A24: 19 | B24: 2457 | C24: Trịnh Thế Hùng | D24: M/M | E24: 45885 | F24: 31 | G24: 5655000 | H24: =ROUND(G24*F24/$C$3,0) -> 5655000 | I24: 6438000 | J24: =ROUND(I24*F24/$C$3,0) -> 6438000 | K24: 3480000 | L24: =ROUND(K24*F24/$C$3,0) -> 3480000 | M24: 1427000 | N24: =ROUND(M24*F24/$C$3,0) -> 1427000 | P24: =ROUND(O24*F24/$C$3,0) -> 0 | Q24: 3500000 | R24: =ROUND(Q24*F24/$C$3,0) -> 3500000 | S24: =ROUND(H24+J24+L24+N24+P24+R24,0) -> 20500000 | T24: =VLOOKUP(B24,'[1]Đi tàu'!$B$7:$F$119,5,FALSE) -> 540000 | U24: =VLOOKUP(B24,[2]T3!$B$7:$F$116,5,FALSE) -> 30000 | V24: =ROUND(100*$V$3,0) -> 2615800 | X24: =S24-T24-U24-V24-W24 -> 17314200 | AA24: =V24/26158 -> 100
C25: Tổng cộng | F25: =SUM(F6:F24) -> 589 | H25: =SUM(H6:H24) -> 207090000 | J25: =SUM(J6:J24) -> 235764000 | L25: =SUM(L6:L24) -> 127440000 | N25: =SUM(N6:N24) -> 96996000 | P25: =SUM(P6:P24) -> 26000000 | R25: =SUM(R6:R24) -> 177110000 | S25: =SUM(S6:S24) -> 870400000 | T25: =SUM(T6:T24) -> 12600000 | U25: =SUM(U6:U24) -> 700000 | V25: =SUM(V6:V24) -> 70626600 | W25: =SUM(W6:W24) -> 0 | X25: =SUM(X6:X24) -> 786473400 | AA25: =SUM(AA6:AA24) -> 2700
Y27: Tp. Hồ Chí Minh, ngày tháng năm 2026
B28: Người lập | D28: P.Trưởng phòng Thuyền viên | S28: Kế toán trưởng | W28: Tổng giám đốc
V30: KHAU TRỪ BHXH | X30: =T25 -> 12600000
V31: KHẤU TRỪ ĐPCĐ | X31: =U25 -> 700000
V32: Lương ĐLGĐ | X32: =X25 -> 786473400
V34: Phân bổ lương ĐLGĐ | X34: =SUM(X30:X33) -> 799773400

Sheet Express
A1: BẢNG THANH TOÁN LƯƠNG THUYỀN VIÊN TÀU INLACO EXPRESS | X1: BẢNG THANH TOÁN LƯƠNG THUYỀN VIÊN TÀU INLACO EXPRESS
A2: THÁNG 3 - 2026 | X2: THÁNG 3 - 2026
C3: 31 | T3: 26158 | W3: Đơn vị tính : VNĐ | Z3: 28 | AS3: 26110 | AV3: Đơn vị tính : VNĐ
A4: Tt | B4: SĐK | C4: Họ và Tên | D4: Chức | E4: Ngày | F4: Ngày | H4: Lương | J4: Ngoài | L4: Tiền | N4: Tiền | P4: Phụ cấp | Q4: Tổng | R4: BHXH | S4: Đoàn phí | T4: TV nhận | U4: Nợ | V4: Lương để lại | W4: Ghi | X4: Tt | Y4: SĐK | Z4: Họ và Tên | AA4: Chức | AB4: Ngày | AC4: Ngày | AE4: Lương | AG4: Ngoài | AI4: Tiền | AK4: Phụ cấp thu | AM4: Phụ cấp vùng | AO4: Phụ cấp | AP4: Tổng | AQ4: BHXH | AR4: Đoàn phí | AS4: TV nhận | AT4: Nợ | AU4: Lương để lại | AV4: Ghi
D5: danh | E5: nhập tàu | F5: công | H5: chính | J5: giờ | L5: phép | N5: phụ cấp | P5: đào tạo | Q5: lương | R5: BHTN | T5: trên tàu | V5: gia đình | W5: chú | AA5: danh | AB5: nhập tàu | AC5: công | AE5: chính | AG5: giờ | AI5: phép | AK5: hút SQTV | AM5: hoạt động | AO5: đào tạo | AP5: lương | AQ5: BHTN | AS5: trên tàu | AU5: gia đình | AV5: chú
A6: 1 | B6: 748 | C6: Thành Anh Duy | D6: Capt. | E6: 45866 | F6: 5 | G6: 24765000 | H6: =ROUND(G6*F6/$C$3,0) -> 3994355 | I6: 28194000 | J6: =ROUND(I6*F6/$C$3,0) -> 4547419 | K6: 15240000 | L6: =ROUND(K6*F6/$C$3,0) -> 2458065 | M6: 6921000 | N6: =ROUND(M6*F6/$C$3,0) -> 1116290 | O6: 14000000 | P6: =ROUND(O6*F6/$C$3,0) -> 2258065 | Q6: =ROUND(H6+J6+L6+N6+P6,0) -> 14374194 | R6: =VLOOKUP(B6,'[1]Đi tàu'!$B$7:$F$119,5,FALSE) -> 1080000 | S6: =VLOOKUP(B6,[2]T3!$B$7:$F$116,5,FALSE) -> 60000 | V6: =ROUND(Q6-R6-S6-T6-U6,0) -> 13234194 | X6: 1 | Y6: 748 | Z6: Thành Anh Duy | AA6: Capt. | AB6: 45866 | AC6: 26 | AD6: 24765000 | AE6: =ROUND(AD6*AC6/$C$3,0) -> 20770645 | AF6: 28194000 | AG6: =ROUND(AF6*AC6/$C$3,0) -> 23646581 | AH6: 15240000 | AI6: =ROUND(AH6*AC6/$C$3,0) -> 12781935 | AJ6: 6921000 | AK6: =ROUND(AJ6*AC6/$C$3,0) -> 5804710 | AL6: 24880000 | AM6: =ROUND(AL6*AC6/$C$3,0) -> 20867097 | AN6: 14000000 | AO6: =ROUND(AN6*AC6/$C$3,0) -> 11741935 | AP6: =ROUND(AE6+AG6+AI6+AK6+AM6+AO6,0) -> 95612903 | AS6: =ROUND(200*$T$3,0) -> 5231600 | AU6: =ROUND(AP6-AQ6-AR6-AS6-AT6,0) -> 90381303
A7: 2 | B7: 2135 | C7: Vũ Tuấn Anh | D7: C/O | E7: 45878 | F7: 5 | G7: 19110000 | H7: =ROUND(G7*F7/$C$3,0) -> 3082258 | I7: 21756000 | J7: =ROUND(I7*F7/$C$3,0) -> 3509032 | K7: 11760000 | L7: =ROUND(K7*F7/$C$3,0) -> 1896774 | M7: 7004000 | N7: =ROUND(M7*F7/$C$3,0) -> 1129677 | P7: =ROUND(O7*F7/$C$3,0) -> 0 | Q7: =ROUND(H7+J7+L7+N7+P7,0) -> 9617741 | R7: =VLOOKUP(B7,'[1]Đi tàu'!$B$7:$F$119,5,FALSE) -> 810000 | S7: =VLOOKUP(B7,[2]T3!$B$7:$F$116,5,FALSE) -> 45000 | V7: =ROUND(Q7-R7-S7-T7-U7,0) -> 8762741 | X7: 2 | Y7: 2135 | Z7: Vũ Tuấn Anh | AA7: C/O | AB7: 45878 | AC7: 26 | AD7: 19110000 | AE7: =ROUND(AD7*AC7/$C$3,0) -> 16027742 | AF7: 21756000 | AG7: =ROUND(AF7*AC7/$C$3,0) -> 18246968 | AH7: 11760000 | AI7: =ROUND(AH7*AC7/$C$3,0) -> 9863226 | AJ7: 7004000 | AK7: =ROUND(AJ7*AC7/$C$3,0) -> 5874323 | AL7: 16670000 | AM7: =ROUND(AL7*AC7/$C$3,0) -> 13981290 | AO7: =ROUND(AN7*AC7/$C$3,0) -> 0 | AP7: =ROUND(AE7+AG7+AI7+AK7+AM7+AO7,0) -> 63993549 | AS7: =ROUND(200*$T$3,0) -> 5231600 | AU7: =ROUND(AP7-AQ7-AR7-AS7-AT7,0) -> 58761949
A8: 3 | B8: 1471 | C8: Ng. Đình Hương | D8: 2/O | E8: 45878 | F8: 5 | G8: 11895000 | H8: =ROUND(G8*F8/$C$3,0) -> 1918548 | I8: 13542000 | J8: =ROUND(I8*F8/$C$3,0) -> 2184194 | K8: 7320000 | L8: =ROUND(K8*F8/$C$3,0) -> 1180645 | M8: 6323000 | N8: =ROUND(M8*F8/$C$3,0) -> 1019839 | P8: =ROUND(O8*F8/$C$3,0) -> 0 | Q8: =ROUND(H8+J8+L8+N8+P8,0) -> 6303226 | R8: =VLOOKUP(B8,'[1]Đi tàu'!$B$7:$F$119,5,FALSE) -> 720000 | S8: =VLOOKUP(B8,[2]T3!$B$7:$F$116,5,FALSE) -> 40000 | V8: =ROUND(Q8-R8-S8-T8-U8,0) -> 5543226 | X8: 3 | Y8: 1471 | Z8: Ng. Đình Hương | AA8: 2/O | AB8: 45878 | AC8: 26 | AD8: 11895000 | AE8: =ROUND(AD8*AC8/$C$3,0) -> 9976452 | AF8: 13542000 | AG8: =ROUND(AF8*AC8/$C$3,0) -> 11357806 | AH8: 7320000 | AI8: =ROUND(AH8*AC8/$C$3,0) -> 6139355 | AJ8: 6323000 | AK8: =ROUND(AJ8*AC8/$C$3,0) -> 5303161 | AL8: 10920000 | AM8: =ROUND(AL8*AC8/$C$3,0) -> 9158710 | AO8: =ROUND(AN8*AC8/$C$3,0) -> 0 | AP8: =ROUND(AE8+AG8+AI8+AK8+AM8+AO8,0) -> 41935484 | AS8: =ROUND(200*$T$3,0) -> 5231600 | AU8: =ROUND(AP8-AQ8-AR8-AS8-AT8,0) -> 36703884
A9: 4 | B9: 2918 | C9: Dương Công Song | D9: 3/O | E9: 45866 | F9: 5 | G9: 10725000 | H9: =ROUND(G9*F9/$C$3,0) -> 1729839 | I9: 12210000 | J9: =ROUND(I9*F9/$C$3,0) -> 1969355 | K9: 6600000 | L9: =ROUND(K9*F9/$C$3,0) -> 1064516 | M9: 6035000 | N9: =ROUND(M9*F9/$C$3,0) -> 973387 | P9: =ROUND(O9*F9/$C$3,0) -> 0 | Q9: =ROUND(H9+J9+L9+N9+P9,0) -> 5737097 | R9: =VLOOKUP(B9,'[1]Đi tàu'!$B$7:$F$119,5,FALSE) -> 675000 | S9: =VLOOKUP(B9,[2]T3!$B$7:$F$116,5,FALSE) -> 37500 | V9: =ROUND(Q9-R9-S9-T9-U9,0) -> 5024597 | X9: 4 | Y9: 2918 | Z9: Dương Công Song | AA9: 3/O | AB9: 45866 | AC9: 26 | AD9: 10725000 | AE9: =ROUND(AD9*AC9/$C$3,0) -> 8995161 | AF9: 12210000 | AG9: =ROUND(AF9*AC9/$C$3,0) -> 10240645 | AH9: 6600000 | AI9: =ROUND(AH9*AC9/$C$3,0) -> 5535484 | AJ9: 6035000 | AK9: =ROUND(AJ9*AC9/$C$3,0) -> 5061613 | AL9: 9930000 | AM9: =ROUND(AL9*AC9/$C$3,0) -> 8328387 | AO9: =ROUND(AN9*AC9/$C$3,0) -> 0 | AP9: =ROUND(AE9+AG9+AI9+AK9+AM9+AO9,0) -> 38161290 | AS9: =ROUND(200*$T$3,0) -> 5231600 | AU9: =ROUND(AP9-AQ9-AR9-AS9-AT9,0) -> 32929690
A10: 5 | B10: 1563 | C10: Ng. Phùng Linh | D10: C/E | E10: 46029 | F10: 5 | G10: 22620000 | H10: =ROUND(G10*F10/$C$3,0) -> 3648387 | I10: 25752000 | J10: =ROUND(I10*F10/$C$3,0) -> 4153548 | K10: 13920000 | L10: =ROUND(K10*F10/$C$3,0) -> 2245161 | M10: 4318000 | N10: =ROUND(M10*F10/$C$3,0) -> 696452 | O10: 12000000 | P10: =ROUND(O10*F10/$C$3,0) -> 1935484 | Q10: =ROUND(H10+J10+L10+N10+P10,0) -> 12679032 | R10: =VLOOKUP(B10,'[1]Đi tàu'!$B$7:$F$119,5,FALSE) -> 1035000 | S10: =VLOOKUP(B10,[2]T3!$B$7:$F$116,5,FALSE) -> 57500 | V10: =ROUND(Q10-R10-S10-T10-U10,0) -> 11586532 | X10: 5 | Y10: 1563 | Z10: Ng. Phùng Linh | AA10: C/E | AB10: 46029 | AC10: 26 | AD10: 22620000 | AE10: =ROUND(AD10*AC10/$C$3,0) -> 18971613 | AF10: 25752000 | AG10: =ROUND(AF10*AC10/$C$3,0) -> 21598452 | AH10: 13920000 | AI10: =ROUND(AH10*AC10/$C$3,0) -> 11674839 | AJ10: 4318000 | AK10: =ROUND(AJ10*AC10/$C$3,0) -> 3621548 | AL10: 21990000 | AM10: =ROUND(AL10*AC10/$C$3,0) -> 18443226 | AN10: 12000000 | AO10: =ROUND(AN10*AC10/$C$3,0) -> 10064516 | AP10: =ROUND(AE10+AG10+AI10+AK10+AM10+AO10,0) -> 84374194 | AS10: =ROUND(200*$T$3,0) -> 5231600 | AU10: =ROUND(AP10-AQ10-AR10-AS10-AT10,0) -> 79142594
A11: 6 | B11: 2285 | C11: Đỗ Xuân Khang | D11: 1/E | E11: 45705 | F11: 5 | G11: 19110000 | H11: =ROUND(G11*F11/$C$3,0) -> 3082258 | I11: 21756000 | J11: =ROUND(I11*F11/$C$3,0) -> 3509032 | K11: 11760000 | L11: =ROUND(K11*F11/$C$3,0) -> 1896774 | M11: 7004000 | N11: =ROUND(M11*F11/$C$3,0) -> 1129677 | P11: =ROUND(O11*F11/$C$3,0) -> 0 | Q11: =ROUND(H11+J11+L11+N11+P11,0) -> 9617741 | R11: =VLOOKUP(B11,'[1]Đi tàu'!$B$7:$F$119,5,FALSE) -> 810000 | S11: =VLOOKUP(B11,[2]T3!$B$7:$F$116,5,FALSE) -> 45000 | V11: =ROUND(Q11-R11-S11-T11-U11,0) -> 8762741 | X11: 6 | Y11: 2285 | Z11: Đỗ Xuân Khang | AA11: 1/E | AB11: 45705 | AC11: 26 | AD11: 19110000 | AE11: =ROUND(AD11*AC11/$C$3,0) -> 16027742 | AF11: 21756000 | AG11: =ROUND(AF11*AC11/$C$3,0) -> 18246968 | AH11: 11760000 | AI11: =ROUND(AH11*AC11/$C$3,0) -> 9863226 | AJ11: 7004000 | AK11: =ROUND(AJ11*AC11/$C$3,0) -> 5874323 | AL11: 16670000 | AM11: =ROUND(AL11*AC11/$C$3,0) -> 13981290 | AO11: =ROUND(AN11*AC11/$C$3,0) -> 0 | AP11: =ROUND(AE11+AG11+AI11+AK11+AM11+AO11,0) -> 63993549 | AS11: =ROUND(200*$T$3,0) -> 5231600 | AU11: =ROUND(AP11-AQ11-AR11-AS11-AT11,0) -> 58761949
A12: 7 | B12: 2249 | C12: Ngô Văn Quyền | D12: 2/E | E12: 45878 | F12: 5 | G12: 11895000 | H12: =ROUND(G12*F12/$C$3,0) -> 1918548 | I12: 13542000 | J12: =ROUND(I12*F12/$C$3,0) -> 2184194 | K12: 7320000 | L12: =ROUND(K12*F12/$C$3,0) -> 1180645 | M12: 6323000 | N12: =ROUND(M12*F12/$C$3,0) -> 1019839 | P12: =ROUND(O12*F12/$C$3,0) -> 0 | Q12: =ROUND(H12+J12+L12+N12+P12,0) -> 6303226 | R12: =VLOOKUP(B12,'[1]Đi tàu'!$B$7:$F$119,5,FALSE) -> 720000 | S12: =VLOOKUP(B12,[2]T3!$B$7:$F$116,5,FALSE) -> 40000 | V12: =ROUND(Q12-R12-S12-T12-U12,0) -> 5543226 | X12: 7 | Y12: 2249 | Z12: Ngô Văn Quyền | AA12: 2/E | AB12: 45878 | AC12: 26 | AD12: 11895000 | AE12: =ROUND(AD12*AC12/$C$3,0) -> 9976452 | AF12: 13542000 | AG12: =ROUND(AF12*AC12/$C$3,0) -> 11357806 | AH12: 7320000 | AI12: =ROUND(AH12*AC12/$C$3,0) -> 6139355 | AJ12: 6323000 | AK12: =ROUND(AJ12*AC12/$C$3,0) -> 5303161 | AL12: 10920000 | AM12: =ROUND(AL12*AC12/$C$3,0) -> 9158710 | AO12: =ROUND(AN12*AC12/$C$3,0) -> 0 | AP12: =ROUND(AE12+AG12+AI12+AK12+AM12+AO12,0) -> 41935484 | AS12: =ROUND(200*$T$3,0) -> 5231600 | AU12: =ROUND(AP12-AQ12-AR12-AS12-AT12,0) -> 36703884
A13: 8 | B13: 2701 | C13: Trần Văn Kiên | D13: 3/E | E13: 45705 | F13: 5 | G13: 10725000 | H13: =ROUND(G13*F13/$C$3,0) -> 1729839 | I13: 12210000 | J13: =ROUND(I13*F13/$C$3,0) -> 1969355 | K13: 6600000 | L13: =ROUND(K13*F13/$C$3,0) -> 1064516 | M13: 6035000 | N13: =ROUND(M13*F13/$C$3,0) -> 973387 | P13: =ROUND(O13*F13/$C$3,0) -> 0 | Q13: =ROUND(H13+J13+L13+N13+P13,0) -> 5737097 | R13: =VLOOKUP(B13,'[1]Đi tàu'!$B$7:$F$119,5,FALSE) -> 675000 | S13: =VLOOKUP(B13,[2]T3!$B$7:$F$116,5,FALSE) -> 37500 | V13: =ROUND(Q13-R13-S13-T13-U13,0) -> 5024597 | W13: Lên 10/8/25 | X13: 8 | Y13: 2701 | Z13: Trần Văn Kiên | AA13: 3/E | AB13: 45705 | AC13: 26 | AD13: 10725000 | AE13: =ROUND(AD13*AC13/$C$3,0) -> 8995161 | AF13: 12210000 | AG13: =ROUND(AF13*AC13/$C$3,0) -> 10240645 | AH13: 6600000 | AI13: =ROUND(AH13*AC13/$C$3,0) -> 5535484 | AJ13: 6035000 | AK13: =ROUND(AJ13*AC13/$C$3,0) -> 5061613 | AL13: 9930000 | AM13: =ROUND(AL13*AC13/$C$3,0) -> 8328387 | AO13: =ROUND(AN13*AC13/$C$3,0) -> 0 | AP13: =ROUND(AE13+AG13+AI13+AK13+AM13+AO13,0) -> 38161290 | AS13: =ROUND(200*$T$3,0) -> 5231600 | AU13: =ROUND(AP13-AQ13-AR13-AS13-AT13,0) -> 32929690 | AV13: Lên 10/8/25
A14: 9 | B14: 2817 | C14: Mai Huy Du | D14: BSN | E14: 45878 | F14: 5 | G14: 8385000 | H14: =ROUND(G14*F14/$C$3,0) -> 1352419 | I14: 9546000 | J14: =ROUND(I14*F14/$C$3,0) -> 1539677 | K14: 5160000 | L14: =ROUND(K14*F14/$C$3,0) -> 832258 | M14: 4909000 | N14: =ROUND(M14*F14/$C$3,0) -> 791774 | P14: =ROUND(O14*F14/$C$3,0) -> 0 | Q14: =ROUND(H14+J14+L14+N14+P14,0) -> 4516128 | R14: =VLOOKUP(B14,'[1]Đi tàu'!$B$7:$F$119,5,FALSE) -> 585000 | S14: =VLOOKUP(B14,[2]T3!$B$7:$F$116,5,FALSE) -> 32500 | V14: =ROUND(Q14-R14-S14-T14-U14,0) -> 3898628 | X14: 9 | Y14: 2817 | Z14: Mai Huy Du | AA14: BSN | AB14: 45878 | AC14: 26 | AD14: 8385000 | AE14: =ROUND(AD14*AC14/$C$3,0) -> 7032581 | AF14: 9546000 | AG14: =ROUND(AF14*AC14/$C$3,0) -> 8006323 | AH14: 5160000 | AI14: =ROUND(AH14*AC14/$C$3,0) -> 4327742 | AJ14: 4909000 | AK14: =ROUND(AJ14*AC14/$C$3,0) -> 4117226 | AL14: 7000000 | AM14: =ROUND(AL14*AC14/$C$3,0) -> 5870968 | AO14: =ROUND(AN14*AC14/$C$3,0) -> 0 | AP14: =ROUND(AE14+AG14+AI14+AK14+AM14+AO14,0) -> 29354840 | AS14: =ROUND(100*$T$3,0) -> 2615800 | AU14: =ROUND(AP14-AQ14-AR14-AS14-AT14,0) -> 26739040
A15: 10 | B15: 2985 | C15: Mai Thanh Hiếu | D15: AB | E15: 45866 | F15: 5 | G15: 6630000 | H15: =ROUND(G15*F15/$C$3,0) -> 1069355 | I15: 7548000 | J15: =ROUND(I15*F15/$C$3,0) -> 1217419 | K15: 4080000 | L15: =ROUND(K15*F15/$C$3,0) -> 658065 | M15: 4742000 | N15: =ROUND(M15*F15/$C$3,0) -> 764839 | P15: =ROUND(O15*F15/$C$3,0) -> 0 | Q15: =ROUND(H15+J15+L15+N15+P15,0) -> 3709678 | R15: =VLOOKUP(B15,'[1]Đi tàu'!$B$7:$F$119,5,FALSE) -> 540000 | S15: =VLOOKUP(B15,[2]T3!$B$7:$F$116,5,FALSE) -> 30000 | V15: =ROUND(Q15-R15-S15-T15-U15,0) -> 3139678 | X15: 10 | Y15: 2985 | Z15: Mai Thanh Hiếu | AA15: AB | AB15: 45866 | AC15: 26 | AD15: 6630000 | AE15: =ROUND(AD15*AC15/$C$3,0) -> 5560645 | AF15: 7548000 | AG15: =ROUND(AF15*AC15/$C$3,0) -> 6330581 | AH15: 4080000 | AI15: =ROUND(AH15*AC15/$C$3,0) -> 3421935 | AJ15: 4742000 | AK15: =ROUND(AJ15*AC15/$C$3,0) -> 3977161 | AL15: 4700000 | AM15: =ROUND(AL15*AC15/$C$3,0) -> 3941935 | AO15: =ROUND(AN15*AC15/$C$3,0) -> 0 | AP15: =ROUND(AE15+AG15+AI15+AK15+AM15+AO15,0) -> 23232257 | AS15: =ROUND(100*$T$3,0) -> 2615800 | AU15: =ROUND(AP15-AQ15-AR15-AS15-AT15,0) -> 20616457
A16: 11 | B16: 2602 | C16: Ng. Viết Quang | D16: AB | E16: 45878 | F16: 5 | G16: 6630000 | H16: =ROUND(G16*F16/$C$3,0) -> 1069355 | I16: 7548000 | J16: =ROUND(I16*F16/$C$3,0) -> 1217419 | K16: 4080000 | L16: =ROUND(K16*F16/$C$3,0) -> 658065 | M16: 4742000 | N16: =ROUND(M16*F16/$C$3,0) -> 764839 | P16: =ROUND(O16*F16/$C$3,0) -> 0 | Q16: =ROUND(H16+J16+L16+N16+P16,0) -> 3709678 | R16: =VLOOKUP(B16,'[1]Đi tàu'!$B$7:$F$119,5,FALSE) -> 540000 | S16: =VLOOKUP(B16,[2]T3!$B$7:$F$116,5,FALSE) -> 30000 | V16: =ROUND(Q16-R16-S16-T16-U16,0) -> 3139678 | X16: 11 | Y16: 2602 | Z16: Ng. Viết Quang | AA16: AB | AB16: 45878 | AC16: 26 | AD16: 6630000 | AE16: =ROUND(AD16*AC16/$C$3,0) -> 5560645 | AF16: 7548000 | AG16: =ROUND(AF16*AC16/$C$3,0) -> 6330581 | AH16: 4080000 | AI16: =ROUND(AH16*AC16/$C$3,0) -> 3421935 | AJ16: 4742000 | AK16: =ROUND(AJ16*AC16/$C$3,0) -> 3977161 | AL16: 4700000 | AM16: =ROUND(AL16*AC16/$C$3,0) -> 3941935 | AO16: =ROUND(AN16*AC16/$C$3,0) -> 0 | AP16: =ROUND(AE16+AG16+AI16+AK16+AM16+AO16,0) -> 23232257 | AS16: =ROUND(100*$T$3,0) -> 2615800 | AU16: =ROUND(AP16-AQ16-AR16-AS16-AT16,0) -> 20616457
A17: 12 | B17: 2843 | C17: Ng. Văn Cường | D17: AB | E17: 46029 | F17: 5 | G17: 6630000 | H17: =ROUND(G17*F17/$C$3,0) -> 1069355 | I17: 7548000 | J17: =ROUND(I17*F17/$C$3,0) -> 1217419 | K17: 4080000 | L17: =ROUND(K17*F17/$C$3,0) -> 658065 | M17: 4742000 | N17: =ROUND(M17*F17/$C$3,0) -> 764839 | P17: =ROUND(O17*F17/$C$3,0) -> 0 | Q17: =ROUND(H17+J17+L17+N17+P17,0) -> 3709678 | R17: =VLOOKUP(B17,'[1]Đi tàu'!$B$7:$F$119,5,FALSE) -> 540000 | S17: =VLOOKUP(B17,[2]T3!$B$7:$F$116,5,FALSE) -> 30000 | V17: =ROUND(Q17-R17-S17-T17-U17,0) -> 3139678 | X17: 12 | Y17: 2843 | Z17: Ng. Văn Cường | AA17: AB | AB17: 46029 | AC17: 26 | AD17: 6630000 | AE17: =ROUND(AD17*AC17/$C$3,0) -> 5560645 | AF17: 7548000 | AG17: =ROUND(AF17*AC17/$C$3,0) -> 6330581 | AH17: 4080000 | AI17: =ROUND(AH17*AC17/$C$3,0) -> 3421935 | AJ17: 4742000 | AK17: =ROUND(AJ17*AC17/$C$3,0) -> 3977161 | AL17: 4700000 | AM17: =ROUND(AL17*AC17/$C$3,0) -> 3941935 | AO17: =ROUND(AN17*AC17/$C$3,0) -> 0 | AP17: =ROUND(AE17+AG17+AI17+AK17+AM17+AO17,0) -> 23232257 | AS17: =ROUND(100*$T$3,0) -> 2615800 | AU17: =ROUND(AP17-AQ17-AR17-AS17-AT17,0) -> 20616457
A18: 13 | B18: 2834 | C18: Hồ Thân Minh | D18: OS | E18: 45878 | F18: 5 | G18: 5655000 | H18: =ROUND(G18*F18/$C$3,0) -> 912097 | I18: 6438000 | J18: =ROUND(I18*F18/$C$3,0) -> 1038387 | K18: 3480000 | L18: =ROUND(K18*F18/$C$3,0) -> 561290 | M18: 2427000 | N18: =ROUND(M18*F18/$C$3,0) -> 391452 | P18: =ROUND(O18*F18/$C$3,0) -> 0 | Q18: =ROUND(H18+J18+L18+N18+P18,0) -> 2903226 | R18: =VLOOKUP(B18,'[1]Đi tàu'!$B$7:$F$119,5,FALSE) -> 540000 | S18: =VLOOKUP(B18,[2]T3!$B$7:$F$116,5,FALSE) -> 30000 | V18: =ROUND(Q18-R18-S18-T18-U18,0) -> 2333226 | X18: 13 | Y18: 2834 | Z18: Hồ Thân Minh | AA18: OS | AB18: 45878 | AC18: 26 | AD18: 5655000 | AE18: =ROUND(AD18*AC18/$C$3,0) -> 4742903 | AF18: 6438000 | AG18: =ROUND(AF18*AC18/$C$3,0) -> 5399613 | AH18: 3480000 | AI18: =ROUND(AH18*AC18/$C$3,0) -> 2918710 | AJ18: 2427000 | AK18: =ROUND(AJ18*AC18/$C$3,0) -> 2035548 | AL18: 3700000 | AM18: =ROUND(AL18*AC18/$C$3,0) -> 3103226 | AO18: =ROUND(AN18*AC18/$C$3,0) -> 0 | AP18: =ROUND(AE18+AG18+AI18+AK18+AM18+AO18,0) -> 18200000 | AS18: =ROUND(100*$T$3,0) -> 2615800 | AU18: =ROUND(AP18-AQ18-AR18-AS18-AT18,0) -> 15584200
A19: 14 | B19: 3003 | C19: Kiều Quốc Huy | D19: OS | E19: 45878 | F19: 5 | G19: 5655000 | H19: =ROUND(G19*F19/$C$3,0) -> 912097 | I19: 6438000 | J19: =ROUND(I19*F19/$C$3,0) -> 1038387 | K19: 3480000 | L19: =ROUND(K19*F19/$C$3,0) -> 561290 | M19: 2427000 | N19: =ROUND(M19*F19/$C$3,0) -> 391452 | P19: =ROUND(O19*F19/$C$3,0) -> 0 | Q19: =ROUND(H19+J19+L19+N19+P19,0) -> 2903226 | R19: =VLOOKUP(B19,'[1]Đi tàu'!$B$7:$F$119,5,FALSE) -> 540000 | S19: =VLOOKUP(B19,[2]T3!$B$7:$F$116,5,FALSE) -> 30000 | V19: =ROUND(Q19-R19-S19-T19-U19,0) -> 2333226 | X19: 14 | Y19: 3003 | Z19: Kiều Quốc Huy | AA19: OS | AB19: 45878 | AC19: 26 | AD19: 5655000 | AE19: =ROUND(AD19*AC19/$C$3,0) -> 4742903 | AF19: 6438000 | AG19: =ROUND(AF19*AC19/$C$3,0) -> 5399613 | AH19: 3480000 | AI19: =ROUND(AH19*AC19/$C$3,0) -> 2918710 | AJ19: 2427000 | AK19: =ROUND(AJ19*AC19/$C$3,0) -> 2035548 | AL19: 3700000 | AM19: =ROUND(AL19*AC19/$C$3,0) -> 3103226 | AO19: =ROUND(AN19*AC19/$C$3,0) -> 0 | AP19: =ROUND(AE19+AG19+AI19+AK19+AM19+AO19,0) -> 18200000 | AS19: =ROUND(100*$T$3,0) -> 2615800 | AU19: =ROUND(AP19-AQ19-AR19-AS19-AT19,0) -> 15584200
A20: 15 | B20: 2789 | C20: Nguyễn Văn Diễn | D20: No.1 | E20: 45878 | F20: 5 | G20: 8385000 | H20: =ROUND(G20*F20/$C$3,0) -> 1352419 | I20: 9546000 | J20: =ROUND(I20*F20/$C$3,0) -> 1539677 | K20: 5160000 | L20: =ROUND(K20*F20/$C$3,0) -> 832258 | M20: 4909000 | N20: =ROUND(M20*F20/$C$3,0) -> 791774 | P20: =ROUND(O20*F20/$C$3,0) -> 0 | Q20: =ROUND(H20+J20+L20+N20+P20,0) -> 4516128 | R20: =VLOOKUP(B20,'[1]Đi tàu'!$B$7:$F$119,5,FALSE) -> 585000 | S20: =VLOOKUP(B20,[2]T3!$B$7:$F$116,5,FALSE) -> 32500 | V20: =ROUND(Q20-R20-S20-T20-U20,0) -> 3898628 | X20: 15 | Y20: 2789 | Z20: Nguyễn Văn Diễn | AA20: No.1 | AB20: 45878 | AC20: 26 | AD20: 8385000 | AE20: =ROUND(AD20*AC20/$C$3,0) -> 7032581 | AF20: 9546000 | AG20: =ROUND(AF20*AC20/$C$3,0) -> 8006323 | AH20: 5160000 | AI20: =ROUND(AH20*AC20/$C$3,0) -> 4327742 | AJ20: 4909000 | AK20: =ROUND(AJ20*AC20/$C$3,0) -> 4117226 | AL20: 7000000 | AM20: =ROUND(AL20*AC20/$C$3,0) -> 5870968 | AO20: =ROUND(AN20*AC20/$C$3,0) -> 0 | AP20: =ROUND(AE20+AG20+AI20+AK20+AM20+AO20,0) -> 29354840 | AS20: =ROUND(100*$T$3,0) -> 2615800 | AU20: =ROUND(AP20-AQ20-AR20-AS20-AT20,0) -> 26739040
A21: 16 | B21: 2827 | C21: Lê Văn Trọng | D21: OLR | E21: 45878 | F21: 5 | G21: 6630000 | H21: =ROUND(G21*F21/$C$3,0) -> 1069355 | I21: 7548000 | J21: =ROUND(I21*F21/$C$3,0) -> 1217419 | K21: 4080000 | L21: =ROUND(K21*F21/$C$3,0) -> 658065 | M21: 4742000 | N21: =ROUND(M21*F21/$C$3,0) -> 764839 | P21: =ROUND(O21*F21/$C$3,0) -> 0 | Q21: =ROUND(H21+J21+L21+N21+P21,0) -> 3709678 | R21: =VLOOKUP(B21,'[1]Đi tàu'!$B$7:$F$119,5,FALSE) -> 540000 | S21: =VLOOKUP(B21,[2]T3!$B$7:$F$116,5,FALSE) -> 30000 | V21: =ROUND(Q21-R21-S21-T21-U21,0) -> 3139678 | X21: 16 | Y21: 2827 | Z21: Lê Văn Trọng | AA21: OLR | AB21: 45878 | AC21: 26 | AD21: 6630000 | AE21: =ROUND(AD21*AC21/$C$3,0) -> 5560645 | AF21: 7548000 | AG21: =ROUND(AF21*AC21/$C$3,0) -> 6330581 | AH21: 4080000 | AI21: =ROUND(AH21*AC21/$C$3,0) -> 3421935 | AJ21: 4742000 | AK21: =ROUND(AJ21*AC21/$C$3,0) -> 3977161 | AL21: 4700000 | AM21: =ROUND(AL21*AC21/$C$3,0) -> 3941935 | AO21: =ROUND(AN21*AC21/$C$3,0) -> 0 | AP21: =ROUND(AE21+AG21+AI21+AK21+AM21+AO21,0) -> 23232257 | AS21: =ROUND(100*$T$3,0) -> 2615800 | AU21: =ROUND(AP21-AQ21-AR21-AS21-AT21,0) -> 20616457
A22: 17 | B22: 2886 | C22: Dương Đình Trường | D22: OLR | E22: 45878 | F22: 5 | G22: 6630000 | H22: =ROUND(G22*F22/$C$3,0) -> 1069355 | I22: 7548000 | J22: =ROUND(I22*F22/$C$3,0) -> 1217419 | K22: 4080000 | L22: =ROUND(K22*F22/$C$3,0) -> 658065 | M22: 4742000 | N22: =ROUND(M22*F22/$C$3,0) -> 764839 | P22: =ROUND(O22*F22/$C$3,0) -> 0 | Q22: =ROUND(H22+J22+L22+N22+P22,0) -> 3709678 | R22: =VLOOKUP(B22,'[1]Đi tàu'!$B$7:$F$119,5,FALSE) -> 540000 | S22: =VLOOKUP(B22,[2]T3!$B$7:$F$116,5,FALSE) -> 30000 | V22: =ROUND(Q22-R22-S22-T22-U22,0) -> 3139678 | X22: 17 | Y22: 2886 | Z22: Dương Đình Trường | AA22: OLR | AB22: 45878 | AC22: 26 | AD22: 6630000 | AE22: =ROUND(AD22*AC22/$C$3,0) -> 5560645 | AF22: 7548000 | AG22: =ROUND(AF22*AC22/$C$3,0) -> 6330581 | AH22: 4080000 | AI22: =ROUND(AH22*AC22/$C$3,0) -> 3421935 | AJ22: 4742000 | AK22: =ROUND(AJ22*AC22/$C$3,0) -> 3977161 | AL22: 4700000 | AM22: =ROUND(AL22*AC22/$C$3,0) -> 3941935 | AO22: =ROUND(AN22*AC22/$C$3,0) -> 0 | AP22: =ROUND(AE22+AG22+AI22+AK22+AM22+AO22,0) -> 23232257 | AS22: =ROUND(100*$T$3,0) -> 2615800 | AU22: =ROUND(AP22-AQ22-AR22-AS22-AT22,0) -> 20616457
A23: 18 | B23: 2912 | C23: Lê Văn Giác | D23: OLR | E23: 45878 | F23: 5 | G23: 6630000 | H23: =ROUND(G23*F23/$C$3,0) -> 1069355 | I23: 7548000 | J23: =ROUND(I23*F23/$C$3,0) -> 1217419 | K23: 4080000 | L23: =ROUND(K23*F23/$C$3,0) -> 658065 | M23: 4742000 | N23: =ROUND(M23*F23/$C$3,0) -> 764839 | P23: =ROUND(O23*F23/$C$3,0) -> 0 | Q23: =ROUND(H23+J23+L23+N23+P23,0) -> 3709678 | R23: =VLOOKUP(B23,'[1]Đi tàu'!$B$7:$F$119,5,FALSE) -> 540000 | S23: =VLOOKUP(B23,[2]T3!$B$7:$F$116,5,FALSE) -> 30000 | V23: =ROUND(Q23-R23-S23-T23-U23,0) -> 3139678 | X23: 18 | Y23: 2912 | Z23: Lê Văn Giác | AA23: OLR | AB23: 45878 | AC23: 26 | AD23: 6630000 | AE23: =ROUND(AD23*AC23/$C$3,0) -> 5560645 | AF23: 7548000 | AG23: =ROUND(AF23*AC23/$C$3,0) -> 6330581 | AH23: 4080000 | AI23: =ROUND(AH23*AC23/$C$3,0) -> 3421935 | AJ23: 4742000 | AK23: =ROUND(AJ23*AC23/$C$3,0) -> 3977161 | AL23: 4700000 | AM23: =ROUND(AL23*AC23/$C$3,0) -> 3941935 | AO23: =ROUND(AN23*AC23/$C$3,0) -> 0 | AP23: =ROUND(AE23+AG23+AI23+AK23+AM23+AO23,0) -> 23232257 | AS23: =ROUND(100*$T$3,0) -> 2615800 | AU23: =ROUND(AP23-AQ23-AR23-AS23-AT23,0) -> 20616457
A24: 19 | B24: 3029 | C24: Lê Quốc Thảo | D24: Elect.O | E24: 45878 | F24: 5 | G24: 7410000 | H24: =ROUND(G24*F24/$C$3,0) -> 1195161 | I24: 8436000 | J24: =ROUND(I24*F24/$C$3,0) -> 1360645 | K24: 4560000 | L24: =ROUND(K24*F24/$C$3,0) -> 735484 | M24: 4594000 | N24: =ROUND(M24*F24/$C$3,0) -> 740968 | P24: =ROUND(O24*F24/$C$3,0) -> 0 | Q24: =ROUND(H24+J24+L24+N24+P24,0) -> 4032258 | R24: =VLOOKUP(B24,'[1]Đi tàu'!$B$7:$F$119,5,FALSE) -> 540000 | S24: =VLOOKUP(B24,[2]T3!$B$7:$F$116,5,FALSE) -> 30000 | V24: =ROUND(Q24-R24-S24-T24-U24,0) -> 3462258 | X24: 19 | Y24: 3029 | Z24: Lê Quốc Thảo | AA24: Elect.O | AB24: 45878 | AC24: 26 | AD24: 7410000 | AE24: =ROUND(AD24*AC24/$C$3,0) -> 6214839 | AF24: 8436000 | AG24: =ROUND(AF24*AC24/$C$3,0) -> 7075355 | AH24: 4560000 | AI24: =ROUND(AH24*AC24/$C$3,0) -> 3824516 | AJ24: 4594000 | AK24: =ROUND(AJ24*AC24/$C$3,0) -> 3853032 | AL24: 5000000 | AM24: =ROUND(AL24*AC24/$C$3,0) -> 4193548 | AO24: =ROUND(AN24*AC24/$C$3,0) -> 0 | AP24: =ROUND(AE24+AG24+AI24+AK24+AM24+AO24,0) -> 25161290 | AS24: =ROUND(100*$T$3,0) -> 2615800 | AU24: =ROUND(AP24-AQ24-AR24-AS24-AT24,0) -> 22545490
A25: 20 | B25: 2929 | C25: Ng. Văn Luật | D25: C/C | E25: 45878 | F25: 5 | G25: 8385000 | H25: =ROUND(G25*F25/$C$3,0) -> 1352419 | I25: 9546000 | J25: =ROUND(I25*F25/$C$3,0) -> 1539677 | K25: 5160000 | L25: =ROUND(K25*F25/$C$3,0) -> 832258 | M25: 4909000 | N25: =ROUND(M25*F25/$C$3,0) -> 791774 | P25: =ROUND(O25*F25/$C$3,0) -> 0 | Q25: =ROUND(H25+J25+L25+N25+P25,0) -> 4516128 | R25: =VLOOKUP(B25,'[1]Đi tàu'!$B$7:$F$119,5,FALSE) -> 585000 | S25: =VLOOKUP(B25,[2]T3!$B$7:$F$116,5,FALSE) -> 32500 | V25: =ROUND(Q25-R25-S25-T25-U25,0) -> 3898628 | X25: 20 | Y25: 2929 | Z25: Ng. Văn Luật | AA25: C/C | AB25: 45878 | AC25: 26 | AD25: 8385000 | AE25: =ROUND(AD25*AC25/$C$3,0) -> 7032581 | AF25: 9546000 | AG25: =ROUND(AF25*AC25/$C$3,0) -> 8006323 | AH25: 5160000 | AI25: =ROUND(AH25*AC25/$C$3,0) -> 4327742 | AJ25: 4909000 | AK25: =ROUND(AJ25*AC25/$C$3,0) -> 4117226 | AL25: 5800000 | AM25: =ROUND(AL25*AC25/$C$3,0) -> 4864516 | AO25: =ROUND(AN25*AC25/$C$3,0) -> 0 | AP25: =ROUND(AE25+AG25+AI25+AK25+AM25+AO25,0) -> 28348388 | AS25: =ROUND(100*$T$3,0) -> 2615800 | AU25: =ROUND(AP25-AQ25-AR25-AS25-AT25,0) -> 25732588
A26: 21 | B26: 3035 | C26: Bùi Trung Hiếu | D26: M/M | E26: 45878 | F26: 5 | G26: 5655000 | H26: =ROUND(G26*F26/$C$3,0) -> 912097 | I26: 6438000 | J26: =ROUND(I26*F26/$C$3,0) -> 1038387 | K26: 3480000 | L26: =ROUND(K26*F26/$C$3,0) -> 561290 | M26: 1427000 | N26: =ROUND(M26*F26/$C$3,0) -> 230161 | P26: =ROUND(O26*F26/$C$3,0) -> 0 | Q26: =ROUND(H26+J26+L26+N26+P26,0) -> 2741935 | R26: =VLOOKUP(B26,'[1]Đi tàu'!$B$7:$F$119,5,FALSE) -> 540000 | S26: =VLOOKUP(B26,[2]T3!$B$7:$F$116,5,FALSE) -> 30000 | V26: =ROUND(Q26-R26-S26-T26-U26,0) -> 2171935 | X26: 21 | Y26: 3035 | Z26: Bùi Trung Hiếu | AA26: M/M | AB26: 45878 | AC26: 26 | AD26: 5655000 | AE26: =ROUND(AD26*AC26/$C$3,0) -> 4742903 | AF26: 6438000 | AG26: =ROUND(AF26*AC26/$C$3,0) -> 5399613 | AH26: 3480000 | AI26: =ROUND(AH26*AC26/$C$3,0) -> 2918710 | AJ26: 1427000 | AK26: =ROUND(AJ26*AC26/$C$3,0) -> 1196839 | AL26: 3500000 | AM26: =ROUND(AL26*AC26/$C$3,0) -> 2935484 | AO26: =ROUND(AN26*AC26/$C$3,0) -> 0 | AP26: =ROUND(AE26+AG26+AI26+AK26+AM26+AO26,0) -> 17193549 | AS26: =ROUND(100*$T$3,0) -> 2615800 | AU26: =ROUND(AP26-AQ26-AR26-AS26-AT26,0) -> 14577749
C27: Tổng cộng | F27: =SUM(F6:F26) -> 105 | H27: =SUM(H6:H26) -> 35508871 | J27: =SUM(J6:J26) -> 40425480 | L27: =SUM(L6:L26) -> 21851614 | N27: =SUM(N6:N26) -> 16776937 | P27: =SUM(P6:P26) -> 4193549 | Q27: =SUM(Q6:Q26) -> 118756451 | R27: =SUM(R6:R26) -> 13680000 | S27: =SUM(S6:S26) -> 760000 | T27: =SUM(T6:T26) -> 0 | U27: =SUM(U6:U26) -> 0 | V27: =SUM(V6:V26) -> 104316451 | Z27: Tổng cộng | AC27: =SUM(AC6:AC26) -> 546 | AE27: =SUM(AE6:AE26) -> 184646129 | AG27: =SUM(AG6:AG26) -> 210212520 | AI27: =SUM(AI6:AI26) -> 113628386 | AK27: =SUM(AK6:AK26) -> 87240063 | AM27: =SUM(AM6:AM26) -> 155840643 | AO27: =SUM(AO6:AO26) -> 21806451 | AP27: =SUM(AP6:AP26) -> 773374192 | AQ27: =SUM(AQ6:AQ26) -> 0 | AR27: =SUM(AR6:AR26) -> 0 | AS27: =SUM(AS6:AS26) -> 75858200 | AT27: =SUM(AT6:AT26) -> 0 | AU27: =SUM(AU6:AU26) -> 697515992
W29: Tp. Hồ Chí Minh, ngày tháng năm 2026 | AV29: Tp. Hồ Chí Minh, ngày tháng năm 2026
B30: Người lập | D30: P.Trưởng phòng Thuyền viên | Q30: Kế toán trưởng | U30: Tổng giám đốc | Y30: Người lập | AA30: P.Trưởng phòng Thuyền viên | AP30: Kế toán trưởng | AT30: Tổng giám đốc

Sheet T.Thuy
A1: BẢNG THANH TOÁN LƯƠNG THUYỀN VIÊN TÀU THANH THỦY
A2: THÁNG 3 - 2026
C3: 31 | V3: 26158 | Y3: Đơn vị tính : VNĐ
A4: Tt | B4: SĐK | C4: Họ và Tên | D4: Chức | E4: Ngày | F4: Ngày | H4: Lương | J4: Ngoài | L4: Tiền | N4: Phụ cấp thu | P4: Phụ cấp theo | R4: Phụ cấp | S4: Tổng | T4: BHXH | U4: Đoàn phí | V4: TV nhận | W4: Nợ | X4: Lương để lại | Y4: Ghi
D5: danh | E5: nhập tàu | F5: công | H5: chính | J5: giờ | L5: phép | N5: hút SQTV | P5: vùng hoạt động | R5: đào tạo | S5: lương | T5: BHTN | V5: trên tàu | X5: gia đình | Y5: chú
A6: 1 | B6: 1300 | C6: Lê Ngọc Lương | D6: Capt. | E6: 45914 | F6: 31 | G6: 22230000 | H6: =ROUND(G6*F6/$C$3,0) -> 22230000 | I6: 25308000 | J6: =ROUND(I6*F6/$C$3,0) -> 25308000 | K6: 13680000 | L6: =ROUND(K6*F6/$C$3,0) -> 13680000 | M6: 6882000 | N6: =ROUND(M6*F6/$C$3,0) -> 6882000 | O6: 13480000 | P6: =ROUND(O6*F6/$C$3,0) -> 13480000 | Q6: 12000000 | R6: =ROUND(Q6*F6/$C$3,0) -> 12000000 | S6: =ROUND(H6+J6+L6+N6+P6+R6,0) -> 93580000 | T6: =VLOOKUP(B6,'[1]Đi tàu'!$B$7:$F$119,5,FALSE) -> 855000 | U6: =VLOOKUP(B6,[2]T3!$B$7:$F$116,5,FALSE) -> 47500 | V6: =ROUND(200*$V$3,0) -> 5231600 | X6: =ROUND(S6-T6-U6-V6-W6,0) -> 87445900
A7: 2 | B7: 1961 | C7: Dư Thành Giảo | D7: C/O | E7: 45914 | F7: 31 | G7: 17160000 | H7: =ROUND(G7*F7/$C$3,0) -> 17160000 | I7: 19536000 | J7: =ROUND(I7*F7/$C$3,0) -> 19536000 | K7: 10560000 | L7: =ROUND(K7*F7/$C$3,0) -> 10560000 | M7: 6354000 | N7: =ROUND(M7*F7/$C$3,0) -> 6354000 | O7: 9000000 | P7: =ROUND(O7*F7/$C$3,0) -> 9000000 | S7: =ROUND(H7+J7+L7+N7+P7+R7,0) -> 62610000 | T7: =VLOOKUP(B7,'[1]Đi tàu'!$B$7:$F$119,5,FALSE) -> 720000 | U7: =VLOOKUP(B7,[2]T3!$B$7:$F$116,5,FALSE) -> 40000 | V7: =ROUND(200*$V$3,0) -> 5231600 | X7: =ROUND(S7-T7-U7-V7-W7,0) -> 56618400
A8: 3 | B8: 1811 | C8: Trần Nam Dân | D8: 2/O | E8: 45728 | F8: 31 | G8: 11310000 | H8: =ROUND(G8*F8/$C$3,0) -> 11310000 | I8: 12876000 | J8: =ROUND(I8*F8/$C$3,0) -> 12876000 | K8: 6960000 | L8: =ROUND(K8*F8/$C$3,0) -> 6960000 | M8: 6934000 | N8: =ROUND(M8*F8/$C$3,0) -> 6934000 | O8: 2950000 | P8: =ROUND(O8*F8/$C$3,0) -> 2950000 | S8: =ROUND(H8+J8+L8+N8+P8+R8,0) -> 41030000 | T8: =VLOOKUP(B8,'[1]Đi tàu'!$B$7:$F$119,5,FALSE) -> 675000 | U8: =VLOOKUP(B8,[2]T3!$B$7:$F$116,5,FALSE) -> 37500 | V8: =ROUND(200*$V$3,0) -> 5231600 | X8: =ROUND(S8-T8-U8-V8-W8,0) -> 35085900
A9: 4 | B9: 2425 | C9: Dương Ngọc Khuê | D9: 3/O | E9: 45728 | F9: 31 | G9: 10140000 | H9: =ROUND(G9*F9/$C$3,0) -> 10140000 | I9: 11544000 | J9: =ROUND(I9*F9/$C$3,0) -> 11544000 | K9: 6240000 | L9: =ROUND(K9*F9/$C$3,0) -> 6240000 | M9: 6136000 | N9: =ROUND(M9*F9/$C$3,0) -> 6136000 | O9: 3290000 | P9: =ROUND(O9*F9/$C$3,0) -> 3290000 | S9: =ROUND(H9+J9+L9+N9+P9+R9,0) -> 37350000 | T9: =VLOOKUP(B9,'[1]Đi tàu'!$B$7:$F$119,5,FALSE) -> 630000 | U9: =VLOOKUP(B9,[2]T3!$B$7:$F$116,5,FALSE) -> 35000 | V9: =ROUND(200*$V$3,0) -> 5231600 | X9: =ROUND(S9-T9-U9-V9-W9,0) -> 31453400
A10: 5 | B10: 1463 | C10: Vũ Khắc Ấn | D10: C/E | E10: 45914 | F10: 31 | G10: 20280000 | H10: =ROUND(G10*F10/$C$3,0) -> 20280000 | I10: 23088000 | J10: =ROUND(I10*F10/$C$3,0) -> 23088000 | K10: 12480000 | L10: =ROUND(K10*F10/$C$3,0) -> 12480000 | M10: 2742000 | N10: =ROUND(M10*F10/$C$3,0) -> 2742000 | O10: 13950000 | P10: =ROUND(O10*F10/$C$3,0) -> 13950000 | Q10: 10000000 | R10: =ROUND(Q10*F10/$C$3,0) -> 10000000 | S10: =ROUND(H10+J10+L10+N10+P10+R10,0) -> 82540000 | T10: =VLOOKUP(B10,'[1]Đi tàu'!$B$7:$F$119,5,FALSE) -> 810000 | U10: =VLOOKUP(B10,[2]T3!$B$7:$F$116,5,FALSE) -> 45000 | V10: =ROUND(200*$V$3,0) -> 5231600 | X10: =ROUND(S10-T10-U10-V10-W10,0) -> 76453400
A11: 6 | B11: 1889 | C11: Trần Minh Phong | D11: 1/E | E11: 45805 | F11: 31 | G11: 17160000 | H11: =ROUND(G11*F11/$C$3,0) -> 17160000 | I11: 19536000 | J11: =ROUND(I11*F11/$C$3,0) -> 19536000 | K11: 10560000 | L11: =ROUND(K11*F11/$C$3,0) -> 10560000 | M11: 6354000 | N11: =ROUND(M11*F11/$C$3,0) -> 6354000 | O11: 9000000 | P11: =ROUND(O11*F11/$C$3,0) -> 9000000 | S11: =ROUND(H11+J11+L11+N11+P11+R11,0) -> 62610000 | T11: =VLOOKUP(B11,'[1]Đi tàu'!$B$7:$F$119,5,FALSE) -> 720000 | U11: =VLOOKUP(B11,[2]T3!$B$7:$F$116,5,FALSE) -> 40000 | V11: =ROUND(200*$V$3,0) -> 5231600 | X11: =ROUND(S11-T11-U11-V11-W11,0) -> 56618400
A12: 7 | B12: 2408 | C12: Trương Quốc Cường | D12: 2/E | E12: 45728 | F12: 31 | G12: 11310000 | H12: =ROUND(G12*F12/$C$3,0) -> 11310000 | I12: 12876000 | J12: =ROUND(I12*F12/$C$3,0) -> 12876000 | K12: 6960000 | L12: =ROUND(K12*F12/$C$3,0) -> 6960000 | M12: 6934000 | N12: =ROUND(M12*F12/$C$3,0) -> 6934000 | O12: 2950000 | P12: =ROUND(O12*F12/$C$3,0) -> 2950000 | S12: =ROUND(H12+J12+L12+N12+P12+R12,0) -> 41030000 | T12: =VLOOKUP(B12,'[1]Đi tàu'!$B$7:$F$119,5,FALSE) -> 675000 | U12: =VLOOKUP(B12,[2]T3!$B$7:$F$116,5,FALSE) -> 37500 | V12: =ROUND(200*$V$3,0) -> 5231600 | X12: =ROUND(S12-T12-U12-V12-W12,0) -> 35085900
A13: 8 | B13: 2431 | C13: Đào Văn Nam | D13: 3/E | E13: 45728 | F13: 31 | G13: 10140000 | H13: =ROUND(G13*F13/$C$3,0) -> 10140000 | I13: 11544000 | J13: =ROUND(I13*F13/$C$3,0) -> 11544000 | K13: 6240000 | L13: =ROUND(K13*F13/$C$3,0) -> 6240000 | M13: 6136000 | N13: =ROUND(M13*F13/$C$3,0) -> 6136000 | O13: 3290000 | P13: =ROUND(O13*F13/$C$3,0) -> 3290000 | S13: =ROUND(H13+J13+L13+N13+P13+R13,0) -> 37350000 | T13: =VLOOKUP(B13,'[1]Đi tàu'!$B$7:$F$119,5,FALSE) -> 630000 | U13: =VLOOKUP(B13,[2]T3!$B$7:$F$116,5,FALSE) -> 35000 | V13: =ROUND(200*$V$3,0) -> 5231600 | X13: =ROUND(S13-T13-U13-V13-W13,0) -> 31453400
A14: 9 | B14: T406 | C14: Phạm Phú Khánh | D14: BSN | E14: 45914 | F14: 31 | G14: 8385000 | H14: =ROUND(G14*F14/$C$3,0) -> 8385000 | I14: 9546000 | J14: =ROUND(I14*F14/$C$3,0) -> 9546000 | K14: 5160000 | L14: =ROUND(K14*F14/$C$3,0) -> 5160000 | M14: 4909000 | N14: =ROUND(M14*F14/$C$3,0) -> 4909000 | O14: 2800000 | P14: =ROUND(O14*F14/$C$3,0) -> 2800000 | S14: =ROUND(H14+J14+L14+N14+P14+R14,0) -> 30800000 | T14: =VLOOKUP(B14,'[1]Đi tàu'!$B$7:$F$119,5,FALSE) -> 585000 | U14: =VLOOKUP(B14,[2]T3!$B$7:$F$116,5,FALSE) -> 32500 | V14: =ROUND(100*$V$3,0) -> 2615800 | X14: =ROUND(S14-T14-U14-V14-W14,0) -> 27566700
A15: 10 | B15: 2755 | C15: Nguyễn Tiến Thuật | D15: AB | E15: 45914 | F15: 31 | G15: 6630000 | H15: =ROUND(G15*F15/$C$3,0) -> 6630000 | I15: 7548000 | J15: =ROUND(I15*F15/$C$3,0) -> 7548000 | K15: 4080000 | L15: =ROUND(K15*F15/$C$3,0) -> 4080000 | M15: 4742000 | N15: =ROUND(M15*F15/$C$3,0) -> 4742000 | O15: 2300000 | P15: =ROUND(O15*F15/$C$3,0) -> 2300000 | S15: =ROUND(H15+J15+L15+N15+P15+R15,0) -> 25300000 | T15: =VLOOKUP(B15,'[1]Đi tàu'!$B$7:$F$119,5,FALSE) -> 540000 | U15: =VLOOKUP(B15,[2]T3!$B$7:$F$116,5,FALSE) -> 30000 | V15: =ROUND(100*$V$3,0) -> 2615800 | X15: =ROUND(S15-T15-U15-V15-W15,0) -> 22114200
A16: 11 | B16: 2889 | C16: Dương Đình Huấn | D16: AB | E16: 45728 | F16: 31 | G16: 6630000 | H16: =ROUND(G16*F16/$C$3,0) -> 6630000 | I16: 7548000 | J16: =ROUND(I16*F16/$C$3,0) -> 7548000 | K16: 4080000 | L16: =ROUND(K16*F16/$C$3,0) -> 4080000 | M16: 4742000 | N16: =ROUND(M16*F16/$C$3,0) -> 4742000 | O16: 2300000 | P16: =ROUND(O16*F16/$C$3,0) -> 2300000 | S16: =ROUND(H16+J16+L16+N16+P16+R16,0) -> 25300000 | T16: =VLOOKUP(B16,'[1]Đi tàu'!$B$7:$F$119,5,FALSE) -> 540000 | U16: =VLOOKUP(B16,[2]T3!$B$7:$F$116,5,FALSE) -> 30000 | V16: =ROUND(100*$V$3,0) -> 2615800 | X16: =ROUND(S16-T16-U16-V16-W16,0) -> 22114200
A17: 12 | B17: 2575 | C17: Lê Ngọc Hồng Sơn | D17: AB | E17: 45728 | F17: 31 | G17: 6630000 | H17: =ROUND(G17*F17/$C$3,0) -> 6630000 | I17: 7548000 | J17: =ROUND(I17*F17/$C$3,0) -> 7548000 | K17: 4080000 | L17: =ROUND(K17*F17/$C$3,0) -> 4080000 | M17: 4742000 | N17: =ROUND(M17*F17/$C$3,0) -> 4742000 | O17: 2300000 | P17: =ROUND(O17*F17/$C$3,0) -> 2300000 | S17: =ROUND(H17+J17+L17+N17+P17+R17,0) -> 25300000 | T17: =VLOOKUP(B17,'[1]Đi tàu'!$B$7:$F$119,5,FALSE) -> 540000 | U17: =VLOOKUP(B17,[2]T3!$B$7:$F$116,5,FALSE) -> 30000 | V17: =ROUND(100*$V$3,0) -> 2615800 | X17: =ROUND(S17-T17-U17-V17-W17,0) -> 22114200
